Workbook

Sheet 26년1~3월
A15: 주일 참석자 현황
A16: 구분 | D16: 날짜 | E16: 45661 | F16: 45668 | G16: 45675 | H16: 45682 | I16: 45689 | J16: 45696 | K16: 45703 | L16: 45710 | M16: 45717 | N16: 45724 | O16: 45731 | P16: 45738 | Q16: 45745
A17: 성인 | E17: =SUMIF(data_주일!I$11:I$303,1,data_주일!I$11:I$303) -> 209 | F17: =SUMIF(data_주일!J$11:J$303,1,data_주일!J$11:J$303) -> 214 | G17: =SUMIF(data_주일!K$11:K$303,1,data_주일!K$11:K$303) -> 217 | H17: =SUMIF(data_주일!L$11:L$303,1,data_주일!L$11:L$303) -> 229 | I17: =SUMIF(data_주일!M$11:M$303,1,data_주일!M$11:M$303) -> 214 | J17: =SUMIF(data_주일!N$11:N$303,1,data_주일!N$11:N$303) -> 216 | K17: =SUM(K18:K27) -> 212 | L17: =SUMIF(data_주일!P$11:P$303,1,data_주일!P$11:P$303) -> 209 | M17: =SUMIF(data_주일!Q$11:Q$303,1,data_주일!Q$11:Q$303) -> 218 | N17: =SUMIF(data_주일!R$11:R$303,1,data_주일!R$11:R$303) -> 211 | O17: =SUMIF(data_주일!S$11:S$303,1,data_주일!S$11:S$303) -> 218 | P17: =SUMIF(data_주일!T$11:T$303,1,data_주일!T$11:T$303) -> 221 | Q17: =SUMIF(data_주일!U$11:U$303,1,data_주일!U$11:U$303) -> 213
B18: 11 | C18: 구역 | D18: 재적39명 | E18: =IF(SUMIF(data_주일!$B$11:$B$303,$B18,data_주일!I$11:I$303)>0,SUMIF(data_주일!$B$11:$B$303,$B18,data_주일!I$11:I$303),"") -> 24 | F18: =IF(SUMIF(data_주일!$B$11:$B$303,$B18,data_주일!J$11:J$303)>0,SUMIF(data_주일!$B$11:$B$303,$B18,data_주일!J$11:J$303),"") -> 24 | G18: =IF(SUMIF(data_주일!$B$11:$B$303,$B18,data_주일!K$11:K$303)>0,SUMIF(data_주일!$B$11:$B$303,$B18,data_주일!K$11:K$303),"") -> 27 | H18: =IF(SUMIF(data_주일!$B$11:$B$303,$B18,data_주일!L$11:L$303)>0,SUMIF(data_주일!$B$11:$B$303,$B18,data_주일!L$11:L$303),"") -> 29 | I18: =IF(SUMIF(data_주일!$B$11:$B$303,$B18,data_주일!M$11:M$303)>0,SUMIF(data_주일!$B$11:$B$303,$B18,data_주일!M$11:M$303),"") -> 26 | J18: =IF(SUMIF(data_주일!$B$11:$B$303,$B18,data_주일!N$11:N$303)>0,SUMIF(data_주일!$B$11:$B$303,$B18,data_주일!N$11:N$303),"") -> 26 | K18: =ROUNDDOWN(AVERAGE(E18:J18),0) -> 26 | L18: =IF(SUMIF(data_주일!$B$11:$B$303,$B18,data_주일!P$11:P$303)>0,SUMIF(data_주일!$B$11:$B$303,$B18,data_주일!P$11:P$303),"") -> 26 | M18: =IF(SUMIF(data_주일!$B$11:$B$303,$B18,data_주일!Q$11:Q$303)>0,SUMIF(data_주일!$B$11:$B$303,$B18,data_주일!Q$11:Q$303),"") -> 26 | N18: =IF(SUMIF(data_주일!$B$11:$B$303,$B18,data_주일!R$11:R$303)>0,SUMIF(data_주일!$B$11:$B$303,$B18,data_주일!R$11:R$303),"") -> 23 | O18: =IF(SUMIF(data_주일!$B$11:$B$303,$B18,data_주일!S$11:S$303)>0,SUMIF(data_주일!$B$11:$B$303,$B18,data_주일!S$11:S$303),"") -> 28 | P18: =IF(SUMIF(data_주일!$B$11:$B$303,$B18,data_주일!T$11:T$303)>0,SUMIF(data_주일!$B$11:$B$303,$B18,data_주일!T$11:T$303),"") -> 26 | Q18: =IF(SUMIF(data_주일!$B$11:$B$303,$B18,data_주일!U$11:U$303)>0,SUMIF(data_주일!$B$11:$B$303,$B18,data_주일!U$11:U$303),"") -> 24
B19: 12 | C19: 구역 | D19: 재적27명 | E19: =IF(SUMIF(data_주일!$B$11:$B$303,$B19,data_주일!I$11:I$303)>0,SUMIF(data_주일!$B$11:$B$303,$B19,data_주일!I$11:I$303),"") -> 25 | F19: =IF(SUMIF(data_주일!$B$11:$B$303,$B19,data_주일!J$11:J$303)>0,SUMIF(data_주일!$B$11:$B$303,$B19,data_주일!J$11:J$303),"") -> 26 | G19: =IF(SUMIF(data_주일!$B$11:$B$303,$B19,data_주일!K$11:K$303)>0,SUMIF(data_주일!$B$11:$B$303,$B19,data_주일!K$11:K$303),"") -> 24 | H19: =IF(SUMIF(data_주일!$B$11:$B$303,$B19,data_주일!L$11:L$303)>0,SUMIF(data_주일!$B$11:$B$303,$B19,data_주일!L$11:L$303),"") -> 27 | I19: =IF(SUMIF(data_주일!$B$11:$B$303,$B19,data_주일!M$11:M$303)>0,SUMIF(data_주일!$B$11:$B$303,$B19,data_주일!M$11:M$303),"") -> 26 | J19: =IF(SUMIF(data_주일!$B$11:$B$303,$B19,data_주일!N$11:N$303)>0,SUMIF(data_주일!$B$11:$B$303,$B19,data_주일!N$11:N$303),"") -> 26 | K19: =ROUNDDOWN(AVERAGE(E19:J19),0) -> 25 | L19: =IF(SUMIF(data_주일!$B$11:$B$303,$B19,data_주일!P$11:P$303)>0,SUMIF(data_주일!$B$11:$B$303,$B19,data_주일!P$11:P$303),"") -> 24 | M19: =IF(SUMIF(data_주일!$B$11:$B$303,$B19,data_주일!Q$11:Q$303)>0,SUMIF(data_주일!$B$11:$B$303,$B19,data_주일!Q$11:Q$303),"") -> 25 | N19: =IF(SUMIF(data_주일!$B$11:$B$303,$B19,data_주일!R$11:R$303)>0,SUMIF(data_주일!$B$11:$B$303,$B19,data_주일!R$11:R$303),"") -> 24 | O19: =IF(SUMIF(data_주일!$B$11:$B$303,$B19,data_주일!S$11:S$303)>0,SUMIF(data_주일!$B$11:$B$303,$B19,data_주일!S$11:S$303),"") -> 27 | P19: =IF(SUMIF(data_주일!$B$11:$B$303,$B19,data_주일!T$11:T$303)>0,SUMIF(data_주일!$B$11:$B$303,$B19,data_주일!T$11:T$303),"") -> 27 | Q19: =IF(SUMIF(data_주일!$B$11:$B$303,$B19,data_주일!U$11:U$303)>0,SUMIF(data_주일!$B$11:$B$303,$B19,data_주일!U$11:U$303),"") -> 28
B20: 21 | C20: 구역 | D20: 재적31명 | E20: =IF(SUMIF(data_주일!$B$11:$B$303,$B20,data_주일!I$11:I$303)>0,SUMIF(data_주일!$B$11:$B$303,$B20,data_주일!I$11:I$303),"") -> 21 | F20: =IF(SUMIF(data_주일!$B$11:$B$303,$B20,data_주일!J$11:J$303)>0,SUMIF(data_주일!$B$11:$B$303,$B20,data_주일!J$11:J$303),"") -> 24 | G20: =IF(SUMIF(data_주일!$B$11:$B$303,$B20,data_주일!K$11:K$303)>0,SUMIF(data_주일!$B$11:$B$303,$B20,data_주일!K$11:K$303),"") -> 26 | H20: =IF(SUMIF(data_주일!$B$11:$B$303,$B20,data_주일!L$11:L$303)>0,SUMIF(data_주일!$B$11:$B$303,$B20,data_주일!L$11:L$303),"") -> 23 | I20: =IF(SUMIF(data_주일!$B$11:$B$303,$B20,data_주일!M$11:M$303)>0,SUMIF(data_주일!$B$11:$B$303,$B20,data_주일!M$11:M$303),"") -> 23 | J20: =IF(SUMIF(data_주일!$B$11:$B$303,$B20,data_주일!N$11:N$303)>0,SUMIF(data_주일!$B$11:$B$303,$B20,data_주일!N$11:N$303),"") -> 22 | K20: =ROUNDDOWN(AVERAGE(E20:J20),0) -> 23 | L20: =IF(SUMIF(data_주일!$B$11:$B$303,$B20,data_주일!P$11:P$303)>0,SUMIF(data_주일!$B$11:$B$303,$B20,data_주일!P$11:P$303),"") -> 22 | M20: =IF(SUMIF(data_주일!$B$11:$B$303,$B20,data_주일!Q$11:Q$303)>0,SUMIF(data_주일!$B$11:$B$303,$B20,data_주일!Q$11:Q$303),"") -> 25 | N20: =IF(SUMIF(data_주일!$B$11:$B$303,$B20,data_주일!R$11:R$303)>0,SUMIF(data_주일!$B$11:$B$303,$B20,data_주일!R$11:R$303),"") -> 22 | O20: =IF(SUMIF(data_주일!$B$11:$B$303,$B20,data_주일!S$11:S$303)>0,SUMIF(data_주일!$B$11:$B$303,$B20,data_주일!S$11:S$303),"") -> 20 | P20: =IF(SUMIF(data_주일!$B$11:$B$303,$B20,data_주일!T$11:T$303)>0,SUMIF(data_주일!$B$11:$B$303,$B20,data_주일!T$11:T$303),"") -> 22 | Q20: =IF(SUMIF(data_주일!$B$11:$B$303,$B20,data_주일!U$11:U$303)>0,SUMIF(data_주일!$B$11:$B$303,$B20,data_주일!U$11:U$303),"") -> 22
B21: 22 | C21: 구역 | D21: 재적23명 | E21: =IF(SUMIF(data_주일!$B$11:$B$303,$B21,data_주일!I$11:I$303)>0,SUMIF(data_주일!$B$11:$B$303,$B21,data_주일!I$11:I$303),"") -> 15 | F21: =IF(SUMIF(data_주일!$B$11:$B$303,$B21,data_주일!J$11:J$303)>0,SUMIF(data_주일!$B$11:$B$303,$B21,data_주일!J$11:J$303),"") -> 16 | G21: =IF(SUMIF(data_주일!$B$11:$B$303,$B21,data_주일!K$11:K$303)>0,SUMIF(data_주일!$B$11:$B$303,$B21,data_주일!K$11:K$303),"") -> 16 | H21: =IF(SUMIF(data_주일!$B$11:$B$303,$B21,data_주일!L$11:L$303)>0,SUMIF(data_주일!$B$11:$B$303,$B21,data_주일!L$11:L$303),"") -> 17 | I21: =IF(SUMIF(data_주일!$B$11:$B$303,$B21,data_주일!M$11:M$303)>0,SUMIF(data_주일!$B$11:$B$303,$B21,data_주일!M$11:M$303),"") -> 17 | J21: =IF(SUMIF(data_주일!$B$11:$B$303,$B21,data_주일!N$11:N$303)>0,SUMIF(data_주일!$B$11:$B$303,$B21,data_주일!N$11:N$303),"") -> 19 | K21: =ROUNDDOWN(AVERAGE(E21:J21),0) -> 16 | L21: =IF(SUMIF(data_주일!$B$11:$B$303,$B21,data_주일!P$11:P$303)>0,SUMIF(data_주일!$B$11:$B$303,$B21,data_주일!P$11:P$303),"") -> 17 | M21: =IF(SUMIF(data_주일!$B$11:$B$303,$B21,data_주일!Q$11:Q$303)>0,SUMIF(data_주일!$B$11:$B$303,$B21,data_주일!Q$11:Q$303),"") -> 20 | N21: =IF(SUMIF(data_주일!$B$11:$B$303,$B21,data_주일!R$11:R$303)>0,SUMIF(data_주일!$B$11:$B$303,$B21,data_주일!R$11:R$303),"") -> 20 | O21: =IF(SUMIF(data_주일!$B$11:$B$303,$B21,data_주일!S$11:S$303)>0,SUMIF(data_주일!$B$11:$B$303,$B21,data_주일!S$11:S$303),"") -> 19 | P21: =IF(SUMIF(data_주일!$B$11:$B$303,$B21,data_주일!T$11:T$303)>0,SUMIF(data_주일!$B$11:$B$303,$B21,data_주일!T$11:T$303),"") -> 20 | Q21: =IF(SUMIF(data_주일!$B$11:$B$303,$B21,data_주일!U$11:U$303)>0,SUMIF(data_주일!$B$11:$B$303,$B21,data_주일!U$11:U$303),"") -> 17
B22: 31 | C22: 구역 | D22: 재적35명 | E22: =IF(SUMIF(data_주일!$B$11:$B$303,$B22,data_주일!I$11:I$303)>0,SUMIF(data_주일!$B$11:$B$303,$B22,data_주일!I$11:I$303),"") -> 29 | F22: =IF(SUMIF(data_주일!$B$11:$B$303,$B22,data_주일!J$11:J$303)>0,SUMIF(data_주일!$B$11:$B$303,$B22,data_주일!J$11:J$303),"") -> 25 | G22: =IF(SUMIF(data_주일!$B$11:$B$303,$B22,data_주일!K$11:K$303)>0,SUMIF(data_주일!$B$11:$B$303,$B22,data_주일!K$11:K$303),"") -> 26 | H22: =IF(SUMIF(data_주일!$B$11:$B$303,$B22,data_주일!L$11:L$303)>0,SUMIF(data_주일!$B$11:$B$303,$B22,data_주일!L$11:L$303),"") -> 28 | I22: =IF(SUMIF(data_주일!$B$11:$B$303,$B22,data_주일!M$11:M$303)>0,SUMIF(data_주일!$B$11:$B$303,$B22,data_주일!M$11:M$303),"") -> 24 | J22: =IF(SUMIF(data_주일!$B$11:$B$303,$B22,data_주일!N$11:N$303)>0,SUMIF(data_주일!$B$11:$B$303,$B22,data_주일!N$11:N$303),"") -> 28 | K22: =ROUNDDOWN(AVERAGE(E22:J22),0) -> 26 | L22: =IF(SUMIF(data_주일!$B$11:$B$303,$B22,data_주일!P$11:P$303)>0,SUMIF(data_주일!$B$11:$B$303,$B22,data_주일!P$11:P$303),"") -> 26 | M22: =IF(SUMIF(data_주일!$B$11:$B$303,$B22,data_주일!Q$11:Q$303)>0,SUMIF(data_주일!$B$11:$B$303,$B22,data_주일!Q$11:Q$303),"") -> 25 | N22: =IF(SUMIF(data_주일!$B$11:$B$303,$B22,data_주일!R$11:R$303)>0,SUMIF(data_주일!$B$11:$B$303,$B22,data_주일!R$11:R$303),"") -> 20 | O22: =IF(SUMIF(data_주일!$B$11:$B$303,$B22,data_주일!S$11:S$303)>0,SUMIF(data_주일!$B$11:$B$303,$B22,data_주일!S$11:S$303),"") -> 23 | P22: =IF(SUMIF(data_주일!$B$11:$B$303,$B22,data_주일!T$11:T$303)>0,SUMIF(data_주일!$B$11:$B$303,$B22,data_주일!T$11:T$303),"") -> 26 | Q22: =IF(SUMIF(data_주일!$B$11:$B$303,$B22,data_주일!U$11:U$303)>0,SUMIF(data_주일!$B$11:$B$303,$B22,data_주일!U$11:U$303),"") -> 24
B23: 32 | C23: 구역 | D23: 재적28명 | E23: =IF(SUMIF(data_주일!$B$11:$B$303,$B23,data_주일!I$11:I$303)>0,SUMIF(data_주일!$B$11:$B$303,$B23,data_주일!I$11:I$303),"") -> 23 | F23: =IF(SUMIF(data_주일!$B$11:$B$303,$B23,data_주일!J$11:J$303)>0,SUMIF(data_주일!$B$11:$B$303,$B23,data_주일!J$11:J$303),"") -> 24 | G23: =IF(SUMIF(data_주일!$B$11:$B$303,$B23,data_주일!K$11:K$303)>0,SUMIF(data_주일!$B$11:$B$303,$B23,data_주일!K$11:K$303),"") -> 26 | H23: =IF(SUMIF(data_주일!$B$11:$B$303,$B23,data_주일!L$11:L$303)>0,SUMIF(data_주일!$B$11:$B$303,$B23,data_주일!L$11:L$303),"") -> 25 | I23: =IF(SUMIF(data_주일!$B$11:$B$303,$B23,data_주일!M$11:M$303)>0,SUMIF(data_주일!$B$11:$B$303,$B23,data_주일!M$11:M$303),"") -> 21 | J23: =IF(SUMIF(data_주일!$B$11:$B$303,$B23,data_주일!N$11:N$303)>0,SUMIF(data_주일!$B$11:$B$303,$B23,data_주일!N$11:N$303),"") -> 27 | K23: =ROUNDDOWN(AVERAGE(E23:J23),0) -> 24 | L23: =IF(SUMIF(data_주일!$B$11:$B$303,$B23,data_주일!P$11:P$303)>0,SUMIF(data_주일!$B$11:$B$303,$B23,data_주일!P$11:P$303),"") -> 23 | M23: =IF(SUMIF(data_주일!$B$11:$B$303,$B23,data_주일!Q$11:Q$303)>0,SUMIF(data_주일!$B$11:$B$303,$B23,data_주일!Q$11:Q$303),"") -> 21 | N23: =IF(SUMIF(data_주일!$B$11:$B$303,$B23,data_주일!R$11:R$303)>0,SUMIF(data_주일!$B$11:$B$303,$B23,data_주일!R$11:R$303),"") -> 26 | O23: =IF(SUMIF(data_주일!$B$11:$B$303,$B23,data_주일!S$11:S$303)>0,SUMIF(data_주일!$B$11:$B$303,$B23,data_주일!S$11:S$303),"") -> 26 | P23: =IF(SUMIF(data_주일!$B$11:$B$303,$B23,data_주일!T$11:T$303)>0,SUMIF(data_주일!$B$11:$B$303,$B23,data_주일!T$11:T$303),"") -> 26 | Q23: =IF(SUMIF(data_주일!$B$11:$B$303,$B23,data_주일!U$11:U$303)>0,SUMIF(data_주일!$B$11:$B$303,$B23,data_주일!U$11:U$303),"") -> 25
B24: 33 | C24: 구역 | D24: 재적12명 | E24: =IF(SUMIF(data_주일!$B$11:$B$303,$B24,data_주일!I$11:I$303)>0,SUMIF(data_주일!$B$11:$B$303,$B24,data_주일!I$11:I$303),"") -> 7 | F24: =IF(SUMIF(data_주일!$B$11:$B$303,$B24,data_주일!J$11:J$303)>0,SUMIF(data_주일!$B$11:$B$303,$B24,data_주일!J$11:J$303),"") -> 6 | G24: =IF(SUMIF(data_주일!$B$11:$B$303,$B24,data_주일!K$11:K$303)>0,SUMIF(data_주일!$B$11:$B$303,$B24,data_주일!K$11:K$303),"") -> 6 | H24: =IF(SUMIF(data_주일!$B$11:$B$303,$B24,data_주일!L$11:L$303)>0,SUMIF(data_주일!$B$11:$B$303,$B24,data_주일!L$11:L$303),"") -> 8 | I24: =IF(SUMIF(data_주일!$B$11:$B$303,$B24,data_주일!M$11:M$303)>0,SUMIF(data_주일!$B$11:$B$303,$B24,data_주일!M$11:M$303),"") -> 6 | J24: =IF(SUMIF(data_주일!$B$11:$B$303,$B24,data_주일!N$11:N$303)>0,SUMIF(data_주일!$B$11:$B$303,$B24,data_주일!N$11:N$303),"") -> 6 | K24: =ROUNDDOWN(AVERAGE(E24:J24),0) -> 6 | L24: =IF(SUMIF(data_주일!$B$11:$B$303,$B24,data_주일!P$11:P$303)>0,SUMIF(data_주일!$B$11:$B$303,$B24,data_주일!P$11:P$303),"") -> 4 | M24: =IF(SUMIF(data_주일!$B$11:$B$303,$B24,data_주일!Q$11:Q$303)>0,SUMIF(data_주일!$B$11:$B$303,$B24,data_주일!Q$11:Q$303),"") -> 6 | N24: =IF(SUMIF(data_주일!$B$11:$B$303,$B24,data_주일!R$11:R$303)>0,SUMIF(data_주일!$B$11:$B$303,$B24,data_주일!R$11:R$303),"") -> 6 | O24: =IF(SUMIF(data_주일!$B$11:$B$303,$B24,data_주일!S$11:S$303)>0,SUMIF(data_주일!$B$11:$B$303,$B24,data_주일!S$11:S$303),"") -> 6 | P24: =IF(SUMIF(data_주일!$B$11:$B$303,$B24,data_주일!T$11:T$303)>0,SUMIF(data_주일!$B$11:$B$303,$B24,data_주일!T$11:T$303),"") -> 4 | Q24: =IF(SUMIF(data_주일!$B$11:$B$303,$B24,data_주일!U$11:U$303)>0,SUMIF(data_주일!$B$11:$B$303,$B24,data_주일!U$11:U$303),"") -> 4
B25: 41 | C25: 구역 | D25: 재적30명 | E25: =IF(SUMIF(data_주일!$B$11:$B$303,$B25,data_주일!I$11:I$303)>0,SUMIF(data_주일!$B$11:$B$303,$B25,data_주일!I$11:I$303),"") -> 20 | F25: =IF(SUMIF(data_주일!$B$11:$B$303,$B25,data_주일!J$11:J$303)>0,SUMIF(data_주일!$B$11:$B$303,$B25,data_주일!J$11:J$303),"") -> 25 | G25: =IF(SUMIF(data_주일!$B$11:$B$303,$B25,data_주일!K$11:K$303)>0,SUMIF(data_주일!$B$11:$B$303,$B25,data_주일!K$11:K$303),"") -> 24 | H25: =IF(SUMIF(data_주일!$B$11:$B$303,$B25,data_주일!L$11:L$303)>0,SUMIF(data_주일!$B$11:$B$303,$B25,data_주일!L$11:L$303),"") -> 24 | I25: =IF(SUMIF(data_주일!$B$11:$B$303,$B25,data_주일!M$11:M$303)>0,SUMIF(data_주일!$B$11:$B$303,$B25,data_주일!M$11:M$303),"") -> 21 | J25: =IF(SUMIF(data_주일!$B$11:$B$303,$B25,data_주일!N$11:N$303)>0,SUMIF(data_주일!$B$11:$B$303,$B25,data_주일!N$11:N$303),"") -> 22 | K25: =ROUNDDOWN(AVERAGE(E25:J25),0) -> 22 | L25: =IF(SUMIF(data_주일!$B$11:$B$303,$B25,data_주일!P$11:P$303)>0,SUMIF(data_주일!$B$11:$B$303,$B25,data_주일!P$11:P$303),"") -> 24 | M25: =IF(SUMIF(data_주일!$B$11:$B$303,$B25,data_주일!Q$11:Q$303)>0,SUMIF(data_주일!$B$11:$B$303,$B25,data_주일!Q$11:Q$303),"") -> 22 | N25: =IF(SUMIF(data_주일!$B$11:$B$303,$B25,data_주일!R$11:R$303)>0,SUMIF(data_주일!$B$11:$B$303,$B25,data_주일!R$11:R$303),"") -> 25 | O25: =IF(SUMIF(data_주일!$B$11:$B$303,$B25,data_주일!S$11:S$303)>0,SUMIF(data_주일!$B$11:$B$303,$B25,data_주일!S$11:S$303),"") -> 23 | P25: =IF(SUMIF(data_주일!$B$11:$B$303,$B25,data_주일!T$11:T$303)>0,SUMIF(data_주일!$B$11:$B$303,$B25,data_주일!T$11:T$303),"") -> 25 | Q25: =IF(SUMIF(data_주일!$B$11:$B$303,$B25,data_주일!U$11:U$303)>0,SUMIF(data_주일!$B$11:$B$303,$B25,data_주일!U$11:U$303),"") -> 26
B26: 42 | C26: 구역 | D26: 재적29명 | E26: =IF(SUMIF(data_주일!$B$11:$B$303,$B26,data_주일!I$11:I$303)>0,SUMIF(data_주일!$B$11:$B$303,$B26,data_주일!I$11:I$303),"") -> 23 | F26: =IF(SUMIF(data_주일!$B$11:$B$303,$B26,data_주일!J$11:J$303)>0,SUMIF(data_주일!$B$11:$B$303,$B26,data_주일!J$11:J$303),"") -> 21 | G26: =IF(SUMIF(data_주일!$B$11:$B$303,$B26,data_주일!K$11:K$303)>0,SUMIF(data_주일!$B$11:$B$303,$B26,data_주일!K$11:K$303),"") -> 20 | H26: =IF(SUMIF(data_주일!$B$11:$B$303,$B26,data_주일!L$11:L$303)>0,SUMIF(data_주일!$B$11:$B$303,$B26,data_주일!L$11:L$303),"") -> 23 | I26: =IF(SUMIF(data_주일!$B$11:$B$303,$B26,data_주일!M$11:M$303)>0,SUMIF(data_주일!$B$11:$B$303,$B26,data_주일!M$11:M$303),"") -> 26 | J26: =IF(SUMIF(data_주일!$B$11:$B$303,$B26,data_주일!N$11:N$303)>0,SUMIF(data_주일!$B$11:$B$303,$B26,data_주일!N$11:N$303),"") -> 20 | K26: =ROUNDDOWN(AVERAGE(E26:J26),0) -> 22 | L26: =IF(SUMIF(data_주일!$B$11:$B$303,$B26,data_주일!P$11:P$303)>0,SUMIF(data_주일!$B$11:$B$303,$B26,data_주일!P$11:P$303),"") -> 22 | M26: =IF(SUMIF(data_주일!$B$11:$B$303,$B26,data_주일!Q$11:Q$303)>0,SUMIF(data_주일!$B$11:$B$303,$B26,data_주일!Q$11:Q$303),"") -> 23 | N26: =IF(SUMIF(data_주일!$B$11:$B$303,$B26,data_주일!R$11:R$303)>0,SUMIF(data_주일!$B$11:$B$303,$B26,data_주일!R$11:R$303),"") -> 22 | O26: =IF(SUMIF(data_주일!$B$11:$B$303,$B26,data_주일!S$11:S$303)>0,SUMIF(data_주일!$B$11:$B$303,$B26,data_주일!S$11:S$303),"") -> 20 | P26: =IF(SUMIF(data_주일!$B$11:$B$303,$B26,data_주일!T$11:T$303)>0,SUMIF(data_주일!$B$11:$B$303,$B26,data_주일!T$11:T$303),"") -> 22 | Q26: =IF(SUMIF(data_주일!$B$11:$B$303,$B26,data_주일!U$11:U$303)>0,SUMIF(data_주일!$B$11:$B$303,$B26,data_주일!U$11:U$303),"") -> 22
B27: 43 | C27: 구역 | D27: 재적34명 | E27: =IF(SUMIF(data_주일!$B$11:$B$303,$B27,data_주일!I$11:I$303)>0,SUMIF(data_주일!$B$11:$B$303,$B27,data_주일!I$11:I$303),"") -> 22 | F27: =IF(SUMIF(data_주일!$B$11:$B$303,$B27,data_주일!J$11:J$303)>0,SUMIF(data_주일!$B$11:$B$303,$B27,data_주일!J$11:J$303),"") -> 23 | G27: =IF(SUMIF(data_주일!$B$11:$B$303,$B27,data_주일!K$11:K$303)>0,SUMIF(data_주일!$B$11:$B$303,$B27,data_주일!K$11:K$303),"") -> 22 | H27: =IF(SUMIF(data_주일!$B$11:$B$303,$B27,data_주일!L$11:L$303)>0,SUMIF(data_주일!$B$11:$B$303,$B27,data_주일!L$11:L$303),"") -> 25 | I27: =IF(SUMIF(data_주일!$B$11:$B$303,$B27,data_주일!M$11:M$303)>0,SUMIF(data_주일!$B$11:$B$303,$B27,data_주일!M$11:M$303),"") -> 24 | J27: =IF(SUMIF(data_주일!$B$11:$B$303,$B27,data_주일!N$11:N$303)>0,SUMIF(data_주일!$B$11:$B$303,$B27,data_주일!N$11:N$303),"") -> 20 | K27: =ROUNDDOWN(AVERAGE(E27:J27),0) -> 22 | L27: =IF(SUMIF(data_주일!$B$11:$B$303,$B27,data_주일!P$11:P$303)>0,SUMIF(data_주일!$B$11:$B$303,$B27,data_주일!P$11:P$303),"") -> 21 | M27: =IF(SUMIF(data_주일!$B$11:$B$303,$B27,data_주일!Q$11:Q$303)>0,SUMIF(data_주일!$B$11:$B$303,$B27,data_주일!Q$11:Q$303),"") -> 25 | N27: =IF(SUMIF(data_주일!$B$11:$B$303,$B27,data_주일!R$11:R$303)>0,SUMIF(data_주일!$B$11:$B$303,$B27,data_주일!R$11:R$303),"") -> 23 | O27: =IF(SUMIF(data_주일!$B$11:$B$303,$B27,data_주일!S$11:S$303)>0,SUMIF(data_주일!$B$11:$B$303,$B27,data_주일!S$11:S$303),"") -> 26 | P27: =IF(SUMIF(data_주일!$B$11:$B$303,$B27,data_주일!T$11:T$303)>0,SUMIF(data_주일!$B$11:$B$303,$B27,data_주일!T$11:T$303),"") -> 23 | Q27: =IF(SUMIF(data_주일!$B$11:$B$303,$B27,data_주일!U$11:U$303)>0,SUMIF(data_주일!$B$11:$B$303,$B27,data_주일!U$11:U$303),"") -> 21
A28: 유초 | E28: 10 | F28: 11 | G28: 12 | H28: 14 | I28: 10 | J28: 8 | K28: =ROUNDDOWN(AVERAGE(E28:J28),0) -> 10 | L28: 9 | M28: 9 | N28: 12 | O28: 11 | P28: 10 | Q28: 9
A29: 중고 | E29: 25 | F29: 21 | G29: 22 | H29: 22 | I29: 21 | J29: 23 | K29: =ROUNDDOWN(AVERAGE(E29:J29),0) -> 22 | L29: 20 | M29: 17 | N29: 20 | O29: 20 | P29: 20 | Q29: 20
A30: 합계 | E30: =SUM(E17,E28,E29) -> 244 | F30: =SUM(F17,F28,F29) -> 246 | G30: =SUM(G17,G28,G29) -> 251 | H30: =SUM(H17,H28,H29) -> 265 | I30: =SUM(I17,I28,I29) -> 245 | J30: =SUM(J17,J28,J29) -> 247 | K30: =SUM(K17,K28,K29) -> 244 | L30: =SUM(L17,L28,L29) -> 238 | ... Q30: =SUM(Q17,Q28,Q29) -> 242
A31: ※ 2월15일 은 설 명절 관계로 평균값(1월4일~2월8일) 입력
A32: ※ 유초등부, 중고등부는 별도 파악하여 입력

Sheet 26년4~5월
A13: 구분 | D13: 날짜 | E13: 45752 | F13: 45759 | G13: 45766 | H13: 45773 | I13: 45780 | J13: 45787 | K13: 45794 | L13: 45801
A14: 성인 | E14: =SUMIF(data_주일!V$11:V$303,1,data_주일!V$11:V$303) -> 197 | F14: =SUMIF(data_주일!W$11:W$303,1,data_주일!W$11:W$303) -> 193 | G14: =SUMIF(data_주일!X$11:X$303,1,data_주일!X$11:X$303) -> 216 | H14: =SUMIF(data_주일!Y$11:Y$303,1,data_주일!Y$11:Y$303) -> 212 | I14: =SUMIF(data_주일!Z$11:Z$303,1,data_주일!Z$11:Z$303) -> 201 | J14: =SUMIF(data_주일!AA$11:AA$303,1,data_주일!AA$11:AA$303) -> 198 | K14: =SUMIF(data_주일!AB$11:AB$303,1,data_주일!AB$11:AB$303) -> 212 | L14: =SUMIF(data_주일!AC$11:AC$303,1,data_주일!AC$11:AC$303) -> 210
B15: 11 | C15: 구역 | D15: 재적39명 | E15: =IF(SUMIF(data_주일!$B$11:$B$303,$B15,data_주일!V$11:V$303)>0,SUMIF(data_주일!$B$11:$B$303,$B15,data_주일!V$11:V$303),"") -> 28 | F15: =IF(SUMIF(data_주일!$B$11:$B$303,$B15,data_주일!W$11:W$303)>0,SUMIF(data_주일!$B$11:$B$303,$B15,data_주일!W$11:W$303),"") -> 16 | G15: =IF(SUMIF(data_주일!$B$11:$B$303,$B15,data_주일!X$11:X$303)>0,SUMIF(data_주일!$B$11:$B$303,$B15,data_주일!X$11:X$303),"") -> 29 | H15: =IF(SUMIF(data_주일!$B$11:$B$303,$B15,data_주일!Y$11:Y$303)>0,SUMIF(data_주일!$B$11:$B$303,$B15,data_주일!Y$11:Y$303),"") -> 26 | I15: =IF(SUMIF(data_주일!$B$11:$B$303,$B15,data_주일!Z$11:Z$303)>0,SUMIF(data_주일!$B$11:$B$303,$B15,data_주일!Z$11:Z$303),"") -> 24 | J15: =IF(SUMIF(data_주일!$B$11:$B$303,$B15,data_주일!AA$11:AA$303)>0,SUMIF(data_주일!$B$11:$B$303,$B15,data_주일!AA$11:AA$303),"") -> 28 | K15: =IF(SUMIF(data_주일!$B$11:$B$303,$B15,data_주일!AB$11:AB$303)>0,SUMIF(data_주일!$B$11:$B$303,$B15,data_주일!AB$11:AB$303),"") -> 22 | L15: =IF(SUMIF(data_주일!$B$11:$B$303,$B15,data_주일!AC$11:AC$303)>0,SUMIF(data_주일!$B$11:$B$303,$B15,data_주일!AC$11:AC$303),"") -> 27
B16: 12 | C16: 구역 | D16: 재적27명 | E16: =IF(SUMIF(data_주일!$B$11:$B$303,$B16,data_주일!V$11:V$303)>0,SUMIF(data_주일!$B$11:$B$303,$B16,data_주일!V$11:V$303),"") -> 22 | F16: =IF(SUMIF(data_주일!$B$11:$B$303,$B16,data_주일!W$11:W$303)>0,SUMIF(data_주일!$B$11:$B$303,$B16,data_주일!W$11:W$303),"") -> 24 | G16: =IF(SUMIF(data_주일!$B$11:$B$303,$B16,data_주일!X$11:X$303)>0,SUMIF(data_주일!$B$11:$B$303,$B16,data_주일!X$11:X$303),"") -> 23 | H16: =IF(SUMIF(data_주일!$B$11:$B$303,$B16,data_주일!Y$11:Y$303)>0,SUMIF(data_주일!$B$11:$B$303,$B16,data_주일!Y$11:Y$303),"") -> 26 | I16: =IF(SUMIF(data_주일!$B$11:$B$303,$B16,data_주일!Z$11:Z$303)>0,SUMIF(data_주일!$B$11:$B$303,$B16,data_주일!Z$11:Z$303),"") -> 27 | J16: =IF(SUMIF(data_주일!$B$11:$B$303,$B16,data_주일!AA$11:AA$303)>0,SUMIF(data_주일!$B$11:$B$303,$B16,data_주일!AA$11:AA$303),"") -> 24 | K16: =IF(SUMIF(data_주일!$B$11:$B$303,$B16,data_주일!AB$11:AB$303)>0,SUMIF(data_주일!$B$11:$B$303,$B16,data_주일!AB$11:AB$303),"") -> 26 | L16: =IF(SUMIF(data_주일!$B$11:$B$303,$B16,data_주일!AC$11:AC$303)>0,SUMIF(data_주일!$B$11:$B$303,$B16,data_주일!AC$11:AC$303),"") -> 26
B17: 21 | C17: 구역 | D17: 재적31명 | E17: =IF(SUMIF(data_주일!$B$11:$B$303,$B17,data_주일!V$11:V$303)>0,SUMIF(data_주일!$B$11:$B$303,$B17,data_주일!V$11:V$303),"") -> 23 | F17: =IF(SUMIF(data_주일!$B$11:$B$303,$B17,data_주일!W$11:W$303)>0,SUMIF(data_주일!$B$11:$B$303,$B17,data_주일!W$11:W$303),"") -> 23 | G17: =IF(SUMIF(data_주일!$B$11:$B$303,$B17,data_주일!X$11:X$303)>0,SUMIF(data_주일!$B$11:$B$303,$B17,data_주일!X$11:X$303),"") -> 26 | H17: =IF(SUMIF(data_주일!$B$11:$B$303,$B17,data_주일!Y$11:Y$303)>0,SUMIF(data_주일!$B$11:$B$303,$B17,data_주일!Y$11:Y$303),"") -> 22 | I17: =IF(SUMIF(data_주일!$B$11:$B$303,$B17,data_주일!Z$11:Z$303)>0,SUMIF(data_주일!$B$11:$B$303,$B17,data_주일!Z$11:Z$303),"") -> 17 | J17: =IF(SUMIF(data_주일!$B$11:$B$303,$B17,data_주일!AA$11:AA$303)>0,SUMIF(data_주일!$B$11:$B$303,$B17,data_주일!AA$11:AA$303),"") -> 20 | K17: =IF(SUMIF(data_주일!$B$11:$B$303,$B17,data_주일!AB$11:AB$303)>0,SUMIF(data_주일!$B$11:$B$303,$B17,data_주일!AB$11:AB$303),"") -> 23 | L17: =IF(SUMIF(data_주일!$B$11:$B$303,$B17,data_주일!AC$11:AC$303)>0,SUMIF(data_주일!$B$11:$B$303,$B17,data_주일!AC$11:AC$303),"") -> 19
B18: 22 | C18: 구역 | D18: 재적23명 | E18: =IF(SUMIF(data_주일!$B$11:$B$303,$B18,data_주일!V$11:V$303)>0,SUMIF(data_주일!$B$11:$B$303,$B18,data_주일!V$11:V$303),"") -> 15 | F18: =IF(SUMIF(data_주일!$B$11:$B$303,$B18,data_주일!W$11:W$303)>0,SUMIF(data_주일!$B$11:$B$303,$B18,data_주일!W$11:W$303),"") -> 19 | G18: =IF(SUMIF(data_주일!$B$11:$B$303,$B18,data_주일!X$11:X$303)>0,SUMIF(data_주일!$B$11:$B$303,$B18,data_주일!X$11:X$303),"") -> 19 | H18: =IF(SUMIF(data_주일!$B$11:$B$303,$B18,data_주일!Y$11:Y$303)>0,SUMIF(data_주일!$B$11:$B$303,$B18,data_주일!Y$11:Y$303),"") -> 14 | I18: =IF(SUMIF(data_주일!$B$11:$B$303,$B18,data_주일!Z$11:Z$303)>0,SUMIF(data_주일!$B$11:$B$303,$B18,data_주일!Z$11:Z$303),"") -> 18 | J18: =IF(SUMIF(data_주일!$B$11:$B$303,$B18,data_주일!AA$11:AA$303)>0,SUMIF(data_주일!$B$11:$B$303,$B18,data_주일!AA$11:AA$303),"") -> 15 | K18: =IF(SUMIF(data_주일!$B$11:$B$303,$B18,data_주일!AB$11:AB$303)>0,SUMIF(data_주일!$B$11:$B$303,$B18,data_주일!AB$11:AB$303),"") -> 17 | L18: =IF(SUMIF(data_주일!$B$11:$B$303,$B18,data_주일!AC$11:AC$303)>0,SUMIF(data_주일!$B$11:$B$303,$B18,data_주일!AC$11:AC$303),"") -> 17
B19: 31 | C19: 구역 | D19: 재적35명 | E19: =IF(SUMIF(data_주일!$B$11:$B$303,$B19,data_주일!V$11:V$303)>0,SUMIF(data_주일!$B$11:$B$303,$B19,data_주일!V$11:V$303),"") -> 21 | F19: =IF(SUMIF(data_주일!$B$11:$B$303,$B19,data_주일!W$11:W$303)>0,SUMIF(data_주일!$B$11:$B$303,$B19,data_주일!W$11:W$303),"") -> 25 | G19: =IF(SUMIF(data_주일!$B$11:$B$303,$B19,data_주일!X$11:X$303)>0,SUMIF(data_주일!$B$11:$B$303,$B19,data_주일!X$11:X$303),"") -> 25 | H19: =IF(SUMIF(data_주일!$B$11:$B$303,$B19,data_주일!Y$11:Y$303)>0,SUMIF(data_주일!$B$11:$B$303,$B19,data_주일!Y$11:Y$303),"") -> 26 | I19: =IF(SUMIF(data_주일!$B$11:$B$303,$B19,data_주일!Z$11:Z$303)>0,SUMIF(data_주일!$B$11:$B$303,$B19,data_주일!Z$11:Z$303),"") -> 20 | J19: =IF(SUMIF(data_주일!$B$11:$B$303,$B19,data_주일!AA$11:AA$303)>0,SUMIF(data_주일!$B$11:$B$303,$B19,data_주일!AA$11:AA$303),"") -> 20 | K19: =IF(SUMIF(data_주일!$B$11:$B$303,$B19,data_주일!AB$11:AB$303)>0,SUMIF(data_주일!$B$11:$B$303,$B19,data_주일!AB$11:AB$303),"") -> 22 | L19: =IF(SUMIF(data_주일!$B$11:$B$303,$B19,data_주일!AC$11:AC$303)>0,SUMIF(data_주일!$B$11:$B$303,$B19,data_주일!AC$11:AC$303),"") -> 22
B20: 32 | C20: 구역 | D20: 재적28명 | E20: =IF(SUMIF(data_주일!$B$11:$B$303,$B20,data_주일!V$11:V$303)>0,SUMIF(data_주일!$B$11:$B$303,$B20,data_주일!V$11:V$303),"") -> 23 | F20: =IF(SUMIF(data_주일!$B$11:$B$303,$B20,data_주일!W$11:W$303)>0,SUMIF(data_주일!$B$11:$B$303,$B20,data_주일!W$11:W$303),"") -> 24 | G20: =IF(SUMIF(data_주일!$B$11:$B$303,$B20,data_주일!X$11:X$303)>0,SUMIF(data_주일!$B$11:$B$303,$B20,data_주일!X$11:X$303),"") -> 24 | H20: =IF(SUMIF(data_주일!$B$11:$B$303,$B20,data_주일!Y$11:Y$303)>0,SUMIF(data_주일!$B$11:$B$303,$B20,data_주일!Y$11:Y$303),"") -> 23 | I20: =IF(SUMIF(data_주일!$B$11:$B$303,$B20,data_주일!Z$11:Z$303)>0,SUMIF(data_주일!$B$11:$B$303,$B20,data_주일!Z$11:Z$303),"") -> 21 | J20: =IF(SUMIF(data_주일!$B$11:$B$303,$B20,data_주일!AA$11:AA$303)>0,SUMIF(data_주일!$B$11:$B$303,$B20,data_주일!AA$11:AA$303),"") -> 22 | K20: =IF(SUMIF(data_주일!$B$11:$B$303,$B20,data_주일!AB$11:AB$303)>0,SUMIF(data_주일!$B$11:$B$303,$B20,data_주일!AB$11:AB$303),"") -> 24 | L20: =IF(SUMIF(data_주일!$B$11:$B$303,$B20,data_주일!AC$11:AC$303)>0,SUMIF(data_주일!$B$11:$B$303,$B20,data_주일!AC$11:AC$303),"") -> 25
B21: 33 | C21: 구역 | D21: 재적12명 | E21: =IF(SUMIF(data_주일!$B$11:$B$303,$B21,data_주일!V$11:V$303)>0,SUMIF(data_주일!$B$11:$B$303,$B21,data_주일!V$11:V$303),"") -> 1 | F21: =IF(SUMIF(data_주일!$B$11:$B$303,$B21,data_주일!W$11:W$303)>0,SUMIF(data_주일!$B$11:$B$303,$B21,data_주일!W$11:W$303),"") -> 5 | G21: =IF(SUMIF(data_주일!$B$11:$B$303,$B21,data_주일!X$11:X$303)>0,SUMIF(data_주일!$B$11:$B$303,$B21,data_주일!X$11:X$303),"") -> 6 | H21: =IF(SUMIF(data_주일!$B$11:$B$303,$B21,data_주일!Y$11:Y$303)>0,SUMIF(data_주일!$B$11:$B$303,$B21,data_주일!Y$11:Y$303),"") -> 6 | I21: =IF(SUMIF(data_주일!$B$11:$B$303,$B21,data_주일!Z$11:Z$303)>0,SUMIF(data_주일!$B$11:$B$303,$B21,data_주일!Z$11:Z$303),"") -> 2 | J21: =IF(SUMIF(data_주일!$B$11:$B$303,$B21,data_주일!AA$11:AA$303)>0,SUMIF(data_주일!$B$11:$B$303,$B21,data_주일!AA$11:AA$303),"") | K21: =IF(SUMIF(data_주일!$B$11:$B$303,$B21,data_주일!AB$11:AB$303)>0,SUMIF(data_주일!$B$11:$B$303,$B21,data_주일!AB$11:AB$303),"") -> 5 | L21: =IF(SUMIF(data_주일!$B$11:$B$303,$B21,data_주일!AC$11:AC$303)>0,SUMIF(data_주일!$B$11:$B$303,$B21,data_주일!AC$11:AC$303),"") -> 4
B22: 41 | C22: 구역 | D22: 재적30명 | E22: =IF(SUMIF(data_주일!$B$11:$B$303,$B22,data_주일!V$11:V$303)>0,SUMIF(data_주일!$B$11:$B$303,$B22,data_주일!V$11:V$303),"") -> 23 | F22: =IF(SUMIF(data_주일!$B$11:$B$303,$B22,data_주일!W$11:W$303)>0,SUMIF(data_주일!$B$11:$B$303,$B22,data_주일!W$11:W$303),"") -> 21 | G22: =IF(SUMIF(data_주일!$B$11:$B$303,$B22,data_주일!X$11:X$303)>0,SUMIF(data_주일!$B$11:$B$303,$B22,data_주일!X$11:X$303),"") -> 20 | H22: =IF(SUMIF(data_주일!$B$11:$B$303,$B22,data_주일!Y$11:Y$303)>0,SUMIF(data_주일!$B$11:$B$303,$B22,data_주일!Y$11:Y$303),"") -> 24 | I22: =IF(SUMIF(data_주일!$B$11:$B$303,$B22,data_주일!Z$11:Z$303)>0,SUMIF(data_주일!$B$11:$B$303,$B22,data_주일!Z$11:Z$303),"") -> 24 | J22: =IF(SUMIF(data_주일!$B$11:$B$303,$B22,data_주일!AA$11:AA$303)>0,SUMIF(data_주일!$B$11:$B$303,$B22,data_주일!AA$11:AA$303),"") -> 23 | K22: =IF(SUMIF(data_주일!$B$11:$B$303,$B22,data_주일!AB$11:AB$303)>0,SUMIF(data_주일!$B$11:$B$303,$B22,data_주일!AB$11:AB$303),"") -> 22 | L22: =IF(SUMIF(data_주일!$B$11:$B$303,$B22,data_주일!AC$11:AC$303)>0,SUMIF(data_주일!$B$11:$B$303,$B22,data_주일!AC$11:AC$303),"") -> 22
B23: 42 | C23: 구역 | D23: 재적29명 | E23: =IF(SUMIF(data_주일!$B$11:$B$303,$B23,data_주일!V$11:V$303)>0,SUMIF(data_주일!$B$11:$B$303,$B23,data_주일!V$11:V$303),"") -> 18 | F23: =IF(SUMIF(data_주일!$B$11:$B$303,$B23,data_주일!W$11:W$303)>0,SUMIF(data_주일!$B$11:$B$303,$B23,data_주일!W$11:W$303),"") -> 13 | G23: =IF(SUMIF(data_주일!$B$11:$B$303,$B23,data_주일!X$11:X$303)>0,SUMIF(data_주일!$B$11:$B$303,$B23,data_주일!X$11:X$303),"") -> 22 | H23: =IF(SUMIF(data_주일!$B$11:$B$303,$B23,data_주일!Y$11:Y$303)>0,SUMIF(data_주일!$B$11:$B$303,$B23,data_주일!Y$11:Y$303),"") -> 19 | I23: =IF(SUMIF(data_주일!$B$11:$B$303,$B23,data_주일!Z$11:Z$303)>0,SUMIF(data_주일!$B$11:$B$303,$B23,data_주일!Z$11:Z$303),"") -> 22 | J23: =IF(SUMIF(data_주일!$B$11:$B$303,$B23,data_주일!AA$11:AA$303)>0,SUMIF(data_주일!$B$11:$B$303,$B23,data_주일!AA$11:AA$303),"") -> 24 | K23: =IF(SUMIF(data_주일!$B$11:$B$303,$B23,data_주일!AB$11:AB$303)>0,SUMIF(data_주일!$B$11:$B$303,$B23,data_주일!AB$11:AB$303),"") -> 23 | L23: =IF(SUMIF(data_주일!$B$11:$B$303,$B23,data_주일!AC$11:AC$303)>0,SUMIF(data_주일!$B$11:$B$303,$B23,data_주일!AC$11:AC$303),"") -> 23
B24: 43 | C24: 구역 | D24: 재적34명 | E24: =IF(SUMIF(data_주일!$B$11:$B$303,$B24,data_주일!V$11:V$303)>0,SUMIF(data_주일!$B$11:$B$303,$B24,data_주일!V$11:V$303),"") -> 23 | F24: =IF(SUMIF(data_주일!$B$11:$B$303,$B24,data_주일!W$11:W$303)>0,SUMIF(data_주일!$B$11:$B$303,$B24,data_주일!W$11:W$303),"") -> 23 | G24: =IF(SUMIF(data_주일!$B$11:$B$303,$B24,data_주일!X$11:X$303)>0,SUMIF(data_주일!$B$11:$B$303,$B24,data_주일!X$11:X$303),"") -> 22 | H24: =IF(SUMIF(data_주일!$B$11:$B$303,$B24,data_주일!Y$11:Y$303)>0,SUMIF(data_주일!$B$11:$B$303,$B24,data_주일!Y$11:Y$303),"") -> 26 | I24: =IF(SUMIF(data_주일!$B$11:$B$303,$B24,data_주일!Z$11:Z$303)>0,SUMIF(data_주일!$B$11:$B$303,$B24,data_주일!Z$11:Z$303),"") -> 26 | J24: =IF(SUMIF(data_주일!$B$11:$B$303,$B24,data_주일!AA$11:AA$303)>0,SUMIF(data_주일!$B$11:$B$303,$B24,data_주일!AA$11:AA$303),"") -> 22 | K24: =IF(SUMIF(data_주일!$B$11:$B$303,$B24,data_주일!AB$11:AB$303)>0,SUMIF(data_주일!$B$11:$B$303,$B24,data_주일!AB$11:AB$303),"") -> 28 | L24: =IF(SUMIF(data_주일!$B$11:$B$303,$B24,data_주일!AC$11:AC$303)>0,SUMIF(data_주일!$B$11:$B$303,$B24,data_주일!AC$11:AC$303),"") -> 25
A25: 유초 | E25: 10 | F25: 12 | G25: 11 | H25: 8 | I25: 8 | J25: 10 | K25: 11 | L25: 8
A26: 중고 | E26: 19 | F26: 21 | G26: 16 | H26: 16 | I26: 17 | J26: 20 | K26: 18 | L26: 17
A27: 합계 | E27: =SUM(E14,E25,E26) -> 226 | F27: =SUM(F14,F25,F26) -> 226 | G27: =SUM(G14,G25,G26) -> 243 | H27: =SUM(H14,H25,H26) -> 236 | I27: =SUM(I14,I25,I26) -> 226 | J27: =SUM(J14,J25,J26) -> 228 | K27: =SUM(K14,K25,K26) -> 241 | L27: =SUM(L14,L25,L26) -> 235
A28: ※ 유초등부, 중고등부는 별도 파악하여 입력
A39: 명단 | B39: 인도자 | D39: 구역 | E39: 45752 | F39: 45759 | G39: 45766 | H39: 45773 | I39: 45780 | J39: 45787 | K39: 45794 | L39: 45801
A40: =IF(data_주일!C309="","",data_주일!C309) -> 윤나영 | B40: =IF(data_주일!D309="","",data_주일!D309) -> 최경숙 | D40: =IF(data_주일!B309="","",data_주일!B309) -> 11 | E40: =IF(data_주일!V309=1,$A40,"") | F40: =IF(data_주일!W309=1,$A40,"") | G40: =IF(data_주일!X309=1,$A40,"") | H40: =IF(data_주일!Y309=1,$A40,"") | I40: =IF(data_주일!Z309=1,$A40,"") | J40: =IF(data_주일!AA309=1,$A40,"") | K40: =IF(data_주일!AB309=1,$A40,"") | L40: =IF(data_주일!AC309=1,$A40,"")
A41: =IF(data_주일!C310="","",data_주일!C310) -> 조미경 | B41: =IF(data_주일!D310="","",data_주일!D310) -> 서금자 | D41: =IF(data_주일!B310="","",data_주일!B310) -> 11 | E41: =IF(data_주일!V310=1,$A41,"") | F41: =IF(data_주일!W310=1,$A41,"") | G41: =IF(data_주일!X310=1,$A41,"") | H41: =IF(data_주일!Y310=1,$A41,"") | I41: =IF(data_주일!Z310=1,$A41,"") -> 조미경 | J41: =IF(data_주일!AA310=1,$A41,"") | K41: =IF(data_주일!AB310=1,$A41,"") | L41: =IF(data_주일!AC310=1,$A41,"")
A42: =IF(data_주일!C311="","",data_주일!C311) -> 차경은 | B42: =IF(data_주일!D311="","",data_주일!D311) -> 이지영 | D42: =IF(data_주일!B311="","",data_주일!B311) -> 11 | E42: =IF(data_주일!V311=1,$A42,"") | F42: =IF(data_주일!W311=1,$A42,"") | G42: =IF(data_주일!X311=1,$A42,"") | H42: =IF(data_주일!Y311=1,$A42,"") | I42: =IF(data_주일!Z311=1,$A42,"") -> 차경은 | J42: =IF(data_주일!AA311=1,$A42,"") | K42: =IF(data_주일!AB311=1,$A42,"") | L42: =IF(data_주일!AC311=1,$A42,"")
A43: =IF(data_주일!C312="","",data_주일!C312) -> 차미나 | B43: =IF(data_주일!D312="","",data_주일!D312) -> 이지영 | D43: =IF(data_주일!B312="","",data_주일!B312) -> 11 | E43: =IF(data_주일!V312=1,$A43,"") | F43: =IF(data_주일!W312=1,$A43,"") | G43: =IF(data_주일!X312=1,$A43,"") | H43: =IF(data_주일!Y312=1,$A43,"") | I43: =IF(data_주일!Z312=1,$A43,"") -> 차미나 | J43: =IF(data_주일!AA312=1,$A43,"") | K43: =IF(data_주일!AB312=1,$A43,"") | L43: =IF(data_주일!AC312=1,$A43,"")
A44: =IF(data_주일!C318="","",data_주일!C318) -> 신현금 | B44: =IF(data_주일!D318="","",data_주일!D318) -> 김재홍 | D44: =IF(data_주일!B318="","",data_주일!B318) -> 21 | E44: =IF(data_주일!V318=1,$A44,"") | F44: =IF(data_주일!W318=1,$A44,"") | G44: =IF(data_주일!X318=1,$A44,"") | H44: =IF(data_주일!Y318=1,$A44,"") | I44: =IF(data_주일!Z318=1,$A44,"") -> 신현금 | J44: =IF(data_주일!AA318=1,$A44,"") | K44: =IF(data_주일!AB318=1,$A44,"") -> 신현금 | L44: =IF(data_주일!AC318=1,$A44,"") -> 신현금
A45: =IF(data_주일!C319="","",data_주일!C319) -> 노정희 | B45: =IF(data_주일!D319="","",data_주일!D319) -> 박점숙 | D45: =IF(data_주일!B319="","",data_주일!B319) -> 21 | E45: =IF(data_주일!V319=1,$A45,"") | F45: =IF(data_주일!W319=1,$A45,"") | G45: =IF(data_주일!X319=1,$A45,"") | H45: =IF(data_주일!Y319=1,$A45,"") | I45: =IF(data_주일!Z319=1,$A45,"") -> 노정희 | J45: =IF(data_주일!AA319=1,$A45,"") | K45: =IF(data_주일!AB319=1,$A45,"") -> 노정희 | L45: =IF(data_주일!AC319=1,$A45,"") -> 노정희
A46: =IF(data_주일!C321="","",data_주일!C321) -> 김창명 | B46: =IF(data_주일!D321="","",data_주일!D321) -> 배미숙 | D46: =IF(data_주일!B321="","",data_주일!B321) -> 22 | E46: =IF(data_주일!V321=1,$A46,"") -> 김창명 | F46: =IF(data_주일!W321=1,$A46,"") | G46: =IF(data_주일!X321=1,$A46,"") | H46: =IF(data_주일!Y321=1,$A46,"") -> 김창명 | I46: =IF(data_주일!Z321=1,$A46,"") -> 김창명 | J46: =IF(data_주일!AA321=1,$A46,"") | K46: =IF(data_주일!AB321=1,$A46,"") -> 김창명 | L46: =IF(data_주일!AC321=1,$A46,"")
A47: =IF(data_주일!C323="","",data_주일!C323) -> 이경옥 | B47: =IF(data_주일!D323="","",data_주일!D323) -> 배미숙 | D47: =IF(data_주일!B323="","",data_주일!B323) -> 22 | E47: =IF(data_주일!V323=1,$A47,"") | F47: =IF(data_주일!W323=1,$A47,"") | G47: =IF(data_주일!X323=1,$A47,"") | H47: =IF(data_주일!Y323=1,$A47,"") | I47: =IF(data_주일!Z323=1,$A47,"") -> 이경옥 | J47: =IF(data_주일!AA323=1,$A47,"") | K47: =IF(data_주일!AB323=1,$A47,"") | L47: =IF(data_주일!AC323=1,$A47,"") -> 이경옥
A48: =IF(data_주일!C325="","",data_주일!C325) -> 정니영 | B48: =IF(data_주일!D325="","",data_주일!D325) -> 박미옥 | D48: =IF(data_주일!B325="","",data_주일!B325) -> 22 | E48: =IF(data_주일!V325=1,$A48,"") | F48: =IF(data_주일!W325=1,$A48,"") | G48: =IF(data_주일!X325=1,$A48,"") | H48: =IF(data_주일!Y325=1,$A48,"") | I48: =IF(data_주일!Z325=1,$A48,"") | J48: =IF(data_주일!AA325=1,$A48,"") | K48: =IF(data_주일!AB325=1,$A48,"") | L48: =IF(data_주일!AC325=1,$A48,"") -> 정니영
A49: =IF(data_주일!C326="","",data_주일!C326) -> 김명선 | B49: =IF(data_주일!D326="","",data_주일!D326) -> 김명선 | D49: =IF(data_주일!B326="","",data_주일!B326) -> 31 | E49: =IF(data_주일!V326=1,$A49,"") | F49: =IF(data_주일!W326=1,$A49,"") | G49: =IF(data_주일!X326=1,$A49,"") | H49: =IF(data_주일!Y326=1,$A49,"") | I49: =IF(data_주일!Z326=1,$A49,"") -> 김명선 | J49: =IF(data_주일!AA326=1,$A49,"") -> 김명선 | K49: =IF(data_주일!AB326=1,$A49,"") -> 김명선 | L49: =IF(data_주일!AC326=1,$A49,"") -> 김명선
A50: =IF(data_주일!C328="","",data_주일!C328) -> 정양선 | B50: =IF(data_주일!D328="","",data_주일!D328) -> 이미화 | D50: =IF(data_주일!B328="","",data_주일!B328) -> 32 | E50: =IF(data_주일!V328=1,$A50,"") | F50: =IF(data_주일!W328=1,$A50,"") | G50: =IF(data_주일!X328=1,$A50,"") | H50: =IF(data_주일!Y328=1,$A50,"") | I50: =IF(data_주일!Z328=1,$A50,"") -> 정양선 | J50: =IF(data_주일!AA328=1,$A50,"") -> 정양선 | K50: =IF(data_주일!AB328=1,$A50,"") | L50: =IF(data_주일!AC328=1,$A50,"")
A51: =IF(data_주일!C329="","",data_주일!C329) -> 최영욱 | B51: =IF(data_주일!D329="","",data_주일!D329) -> 최명희 | D51: =IF(data_주일!B329="","",data_주일!B329) -> 32 | E51: =IF(data_주일!V329=1,$A51,"") | F51: =IF(data_주일!W329=1,$A51,"") | G51: =IF(data_주일!X329=1,$A51,"") | H51: =IF(data_주일!Y329=1,$A51,"") | I51: =IF(data_주일!Z329=1,$A51,"") | J51: =IF(data_주일!AA329=1,$A51,"") | K51: =IF(data_주일!AB329=1,$A51,"") | L51: =IF(data_주일!AC329=1,$A51,"")
A52: =IF(data_주일!C330="","",data_주일!C330) -> 최명희 | B52: =IF(data_주일!D330="","",data_주일!D330) -> 윤영희 | D52: =IF(data_주일!B330="","",data_주일!B330) -> 32 | E52: =IF(data_주일!V330=1,$A52,"") | F52: =IF(data_주일!W330=1,$A52,"") | G52: =IF(data_주일!X330=1,$A52,"") | H52: =IF(data_주일!Y330=1,$A52,"") | I52: =IF(data_주일!Z330=1,$A52,"") | J52: =IF(data_주일!AA330=1,$A52,"") | K52: =IF(data_주일!AB330=1,$A52,"") | L52: =IF(data_주일!AC330=1,$A52,"")
A53: =IF(data_주일!C331="","",data_주일!C331) -> 이예인 | B53: =IF(data_주일!D331="","",data_주일!D331) -> 오은경 | D53: =IF(data_주일!B331="","",data_주일!B331) -> 32 | E53: =IF(data_주일!V331=1,$A53,"") | F53: =IF(data_주일!W331=1,$A53,"") | G53: =IF(data_주일!X331=1,$A53,"") | H53: =IF(data_주일!Y331=1,$A53,"") | I53: =IF(data_주일!Z331=1,$A53,"") | J53: =IF(data_주일!AA331=1,$A53,"") | K53: =IF(data_주일!AB331=1,$A53,"") | L53: =IF(data_주일!AC331=1,$A53,"") -> 이예인
A54: =IF(data_주일!C332="","",data_주일!C332) -> 오상진 | B54: =IF(data_주일!D332="","",data_주일!D332) -> 최명희 | D54: =IF(data_주일!B332="","",data_주일!B332) -> 32 | E54: =IF(data_주일!V332=1,$A54,"") | F54: =IF(data_주일!W332=1,$A54,"") | G54: =IF(data_주일!X332=1,$A54,"") | H54: =IF(data_주일!Y332=1,$A54,"") | I54: =IF(data_주일!Z332=1,$A54,"") | J54: =IF(data_주일!AA332=1,$A54,"") | K54: =IF(data_주일!AB332=1,$A54,"") | L54: =IF(data_주일!AC332=1,$A54,"") -> 오상진
A55: =IF(data_주일!C335="","",data_주일!C335) -> 김예솔 | B55: =IF(data_주일!D335="","",data_주일!D335) -> 백종애 | D55: =IF(data_주일!B335="","",data_주일!B335) -> 41 | E55: =IF(data_주일!V335=1,$A55,"") | F55: =IF(data_주일!W335=1,$A55,"") | G55: =IF(data_주일!X335=1,$A55,"") | H55: =IF(data_주일!Y335=1,$A55,"") | I55: =IF(data_주일!Z335=1,$A55,"") -> 김예솔 | J55: =IF(data_주일!AA335=1,$A55,"") -> 김예솔 | K55: =IF(data_주일!AB335=1,$A55,"") -> 김예솔 | L55: =IF(data_주일!AC335=1,$A55,"") -> 김예솔
A56: =IF(data_주일!C336="","",data_주일!C336) -> 허수희 | B56: =IF(data_주일!D336="","",data_주일!D336) -> 이지영 | D56: =IF(data_주일!B336="","",data_주일!B336) -> 41 | E56: =IF(data_주일!V336=1,$A56,"") | F56: =IF(data_주일!W336=1,$A56,"") | G56: =IF(data_주일!X336=1,$A56,"") | H56: =IF(data_주일!Y336=1,$A56,"") | I56: =IF(data_주일!Z336=1,$A56,"") | J56: =IF(data_주일!AA336=1,$A56,"") | K56: =IF(data_주일!AB336=1,$A56,"") | L56: =IF(data_주일!AC336=1,$A56,"")
A57: =IF(data_주일!C337="","",data_주일!C337) -> 김성수 | B57: =IF(data_주일!D337="","",data_주일!D337) -> 박성찬 | D57: =IF(data_주일!B337="","",data_주일!B337) -> 42 | E57: =IF(data_주일!V337=1,$A57,"") | F57: =IF(data_주일!W337=1,$A57,"") | G57: =IF(data_주일!X337=1,$A57,"") | H57: =IF(data_주일!Y337=1,$A57,"") | I57: =IF(data_주일!Z337=1,$A57,"") | J57: =IF(data_주일!AA337=1,$A57,"") | K57: =IF(data_주일!AB337=1,$A57,"") | L57: =IF(data_주일!AC337=1,$A57,"")
A58: =IF(data_주일!C338="","",data_주일!C338) -> 이남경 | B58: =IF(data_주일!D338="","",data_주일!D338) -> 김성수 | D58: =IF(data_주일!B338="","",data_주일!B338) -> 42 | E58: =IF(data_주일!V338=1,$A58,"") | F58: =IF(data_주일!W338=1,$A58,"") | G58: =IF(data_주일!X338=1,$A58,"") | H58: =IF(data_주일!Y338=1,$A58,"") | I58: =IF(data_주일!Z338=1,$A58,"") | J58: =IF(data_주일!AA338=1,$A58,"") | K58: =IF(data_주일!AB338=1,$A58,"") | L58: =IF(data_주일!AC338=1,$A58,"")
A59: =IF(data_주일!C339="","",data_주일!C339) -> 김광홍 | B59: =IF(data_주일!D339="","",data_주일!D339) -> 서영석 | D59: =IF(data_주일!B339="","",data_주일!B339) -> 43 | E59: =IF(data_주일!V339=1,$A59,"") | F59: =IF(data_주일!W339=1,$A59,"") | G59: =IF(data_주일!X339=1,$A59,"") | H59: =IF(data_주일!Y339=1,$A59,"") | I59: =IF(data_주일!Z339=1,$A59,"") | J59: =IF(data_주일!AA339=1,$A59,"") | K59: =IF(data_주일!AB339=1,$A59,"") | L59: =IF(data_주일!AC339=1,$A59,"")
A60: =IF(data_주일!C340="","",data_주일!C340) | B60: =IF(data_주일!D340="","",data_주일!D340) | D60: =IF(data_주일!B340="","",data_주일!B340) | E60: =IF(data_주일!V340=1,$A60,"") | F60: =IF(data_주일!W340=1,$A60,"") | G60: =IF(data_주일!X340=1,$A60,"") | H60: =IF(data_주일!Y340=1,$A60,"") | I60: =IF(data_주일!Z340=1,$A60,"") | J60: =IF(data_주일!AA340=1,$A60,"") | K60: =IF(data_주일!AB340=1,$A60,"") | L60: =IF(data_주일!AC340=1,$A60,"")
A61: 계 | E61: =COUNTA(E40:E55)-COUNTIF(E40:E55,"") -> 1 | F61: =COUNTA(F40:F55)-COUNTIF(F40:F55,"") -> 0 | G61: =COUNTA(G40:G55)-COUNTIF(G40:G55,"") -> 0 | H61: =COUNTA(H40:H55)-COUNTIF(H40:H55,"") -> 1 | I61: =COUNTA(I40:I55)-COUNTIF(I40:I55,"") -> 10 | J61: =COUNTA(J40:J55)-COUNTIF(J40:J55,"") -> 3 | K61: =COUNTA(K40:K55)-COUNTIF(K40:K55,"") -> 5 | L61: =COUNTA(L40:L55)-COUNTIF(L40:L55,"") -> 8
A62: ※ 새참자: 주소록에 등록되지 않은 분으로 주일에 성경강연회(인터넷) 말씀 또는 주일 말씀을 듣기위해 방문하신 분

Sheet 26년5~6월
C13: 구분 | F13: 날짜 | G13: 45752 | H13: 45759 | I13: 45766 | J13: 45773 | K13: 45780 | L13: 45787 | M13: 45794 | N13: 45801 | O13: 45808 | P13: 45815 | Q13: 45822 | R13: 45829 | S13: 45835 | T13: 한달 평균
C14: 성인 | F14: 288 | G14: =SUMIF(data_주일!V$11:V$303,1,data_주일!V$11:V$303) -> 197 | H14: =SUMIF(data_주일!W$11:W$303,1,data_주일!W$11:W$303) -> 193 | I14: =SUMIF(data_주일!X$11:X$303,1,data_주일!X$11:X$303) -> 216 | J14: =SUMIF(data_주일!Y$11:Y$303,1,data_주일!Y$11:Y$303) -> 212 | K14: =IF(SUMIF(data_주일!Z$11:Z$303,1,data_주일!Z$11:Z$303)>0,SUMIF(data_주일!Z$11:Z$303,1,data_주일!Z$11:Z$303),"") -> 201 | L14: =IF(SUMIF(data_주일!AA$11:AA$303,1,data_주일!AA$11:AA$303)>0,SUMIF(data_주일!AA$11:AA$303,1,data_주일!AA$11:AA$303),"") -> 198 | M14: =IF(SUMIF(data_주일!AB$11:AB$303,1,data_주일!AB$11:AB$303)>0,SUMIF(data_주일!AB$11:AB$303,1,data_주일!AB$11:AB$303),"") -> 212 | N14: =IF(SUMIF(data_주일!AC$11:AC$303,1,data_주일!AC$11:AC$303)>0,SUMIF(data_주일!AC$11:AC$303,1,data_주일!AC$11:AC$303),"") -> 210 | O14: =IF(SUMIF(data_주일!AD$11:AD$303,1,data_주일!AD$11:AD$303)>0,SUMIF(data_주일!AD$11:AD$303,1,data_주일!AD$11:AD$303),"") -> 206 | P14: =IF(SUMIF(data_주일!AE$11:AE$303,1,data_주일!AE$11:AE$303)>0,SUMIF(data_주일!AE$11:AE$303,1,data_주일!AE$11:AE$303),"") -> 215 | Q14: =IF(SUMIF(data_주일!AF$11:AF$303,1,data_주일!AF$11:AF$303)>0,SUMIF(data_주일!AF$11:AF$303,1,data_주일!AF$11:AF$303),"") -> 206 | R14: =IF(SUMIF(data_주일!AF$11:AF$303,1,data_주일!AF$11:AF$303)>0,SUMIF(data_주일!AF$11:AF$303,1,data_주일!AF$11:AF$303),"") -> 206 | S14: =IF(SUMIF(data_주일!AG$11:AG$303,1,data_주일!AG$11:AG$303)>0,SUMIF(data_주일!AG$11:AG$303,1,data_주일!AG$11:AG$303),"") -> 202 | T14: =AVERAGE(M14:Q14) -> 209.8
D15: 구역 | F15: 재적 | G15: =IFERROR(G14/$F$14,"") -> 0.68402778 | H15: =IFERROR(H14/$F$14,"") -> 0.67013889 | I15: =IFERROR(I14/$F$14,"") -> 0.75 | J15: =IFERROR(J14/$F$14,"") -> 0.73611111 | K15: =IFERROR(K14/$F$14,"") -> 0.69791667 | L15: =IFERROR(L14/$F$14,"") -> 0.6875 | M15: =IFERROR(M14/$F$14,"") -> 0.73611111 | N15: =IFERROR(N14/$F$14,"") -> 0.72916667 | ... S15: =IFERROR(S14/$F$14,"") -> 0.70138889 | T15: =AVERAGE(M15:Q15) -> 0.72847222
D16: 11 | F16: 39 | G16: =IF(SUMIF(data_주일!$B$11:$B$303,$D16,data_주일!V$11:V$303)>0,SUMIF(data_주일!$B$11:$B$303,$D16,data_주일!V$11:V$303),"") -> 28 | H16: =IF(SUMIF(data_주일!$B$11:$B$303,$D16,data_주일!W$11:W$303)>0,SUMIF(data_주일!$B$11:$B$303,$D16,data_주일!W$11:W$303),"") -> 16 | I16: =IF(SUMIF(data_주일!$B$11:$B$303,$D16,data_주일!X$11:X$303)>0,SUMIF(data_주일!$B$11:$B$303,$D16,data_주일!X$11:X$303),"") -> 29 | J16: =IF(SUMIF(data_주일!$B$11:$B$303,$D16,data_주일!Y$11:Y$303)>0,SUMIF(data_주일!$B$11:$B$303,$D16,data_주일!Y$11:Y$303),"") -> 26 | K16: =IF(SUMIF(data_주일!$B$11:$B$303,$D16,data_주일!Z$11:Z$303)>0,SUMIF(data_주일!$B$11:$B$303,$D16,data_주일!Z$11:Z$303),"") -> 24 | L16: =IF(SUMIF(data_주일!$B$11:$B$303,$D16,data_주일!AA$11:AA$303)>0,SUMIF(data_주일!$B$11:$B$303,$D16,data_주일!AA$11:AA$303),"") -> 28 | M16: =IF(SUMIF(data_주일!$B$11:$B$303,$D16,data_주일!AB$11:AB$303)>0,SUMIF(data_주일!$B$11:$B$303,$D16,data_주일!AB$11:AB$303),"") -> 22 | N16: =IF(SUMIF(data_주일!$B$11:$B$303,$D16,data_주일!AC$11:AC$303)>0,SUMIF(data_주일!$B$11:$B$303,$D16,data_주일!AC$11:AC$303),"") -> 27 | O16: =IF(SUMIF(data_주일!$B$11:$B$303,$D16,data_주일!AD$11:AD$303)>0,SUMIF(data_주일!$B$11:$B$303,$D16,data_주일!AD$11:AD$303),"") -> 25 | P16: =IF(SUMIF(data_주일!$B:$B,$D16,data_주일!AE$1:AE$303)>0,SUMIF(data_주일!$B:$B,$D16,data_주일!AE$1:AE$303),"") -> 28 | Q16: =IF(SUMIF(data_주일!$B:$B,$D16,data_주일!AF$1:AF$303)>0,SUMIF(data_주일!$B:$B,$D16,data_주일!AF$1:AF$303),"") -> 24 | R16: =IF(SUMIF(data_주일!$B:$B,$D16,data_주일!AF$1:AF$303)>0,SUMIF(data_주일!$B:$B,$D16,data_주일!AF$1:AF$303),"") -> 24 | S16: =IF(SUMIF(data_주일!$B:$B,$D16,data_주일!AG$1:AG$303)>0,SUMIF(data_주일!$B:$B,$D16,data_주일!AG$1:AG$303),"") -> 23 | T16: =AVERAGE(M16:Q16) -> 25.2
D17: 12 | F17: 27 | G17: =IF(SUMIF(data_주일!$B$11:$B$303,$D17,data_주일!V$11:V$303)>0,SUMIF(data_주일!$B$11:$B$303,$D17,data_주일!V$11:V$303),"") -> 22 | H17: =IF(SUMIF(data_주일!$B$11:$B$303,$D17,data_주일!W$11:W$303)>0,SUMIF(data_주일!$B$11:$B$303,$D17,data_주일!W$11:W$303),"") -> 24 | I17: =IF(SUMIF(data_주일!$B$11:$B$303,$D17,data_주일!X$11:X$303)>0,SUMIF(data_주일!$B$11:$B$303,$D17,data_주일!X$11:X$303),"") -> 23 | J17: =IF(SUMIF(data_주일!$B$11:$B$303,$D17,data_주일!Y$11:Y$303)>0,SUMIF(data_주일!$B$11:$B$303,$D17,data_주일!Y$11:Y$303),"") -> 26 | K17: =IF(SUMIF(data_주일!$B$11:$B$303,$D17,data_주일!Z$11:Z$303)>0,SUMIF(data_주일!$B$11:$B$303,$D17,data_주일!Z$11:Z$303),"") -> 27 | L17: =IF(SUMIF(data_주일!$B$11:$B$303,$D17,data_주일!AA$11:AA$303)>0,SUMIF(data_주일!$B$11:$B$303,$D17,data_주일!AA$11:AA$303),"") -> 24 | M17: =IF(SUMIF(data_주일!$B$11:$B$303,$D17,data_주일!AB$11:AB$303)>0,SUMIF(data_주일!$B$11:$B$303,$D17,data_주일!AB$11:AB$303),"") -> 26 | N17: =IF(SUMIF(data_주일!$B$11:$B$303,$D17,data_주일!AC$11:AC$303)>0,SUMIF(data_주일!$B$11:$B$303,$D17,data_주일!AC$11:AC$303),"") -> 26 | O17: =IF(SUMIF(data_주일!$B$11:$B$303,$D17,data_주일!AD$11:AD$303)>0,SUMIF(data_주일!$B$11:$B$303,$D17,data_주일!AD$11:AD$303),"") -> 23 | P17: =IF(SUMIF(data_주일!$B:$B,$D17,data_주일!AE$1:AE$303)>0,SUMIF(data_주일!$B:$B,$D17,data_주일!AE$1:AE$303),"") -> 26 | Q17: =IF(SUMIF(data_주일!$B:$B,$D17,data_주일!AF$1:AF$303)>0,SUMIF(data_주일!$B:$B,$D17,data_주일!AF$1:AF$303),"") -> 28 | R17: =IF(SUMIF(data_주일!$B:$B,$D17,data_주일!AF$1:AF$303)>0,SUMIF(data_주일!$B:$B,$D17,data_주일!AF$1:AF$303),"") -> 28 | S17: =IF(SUMIF(data_주일!$B:$B,$D17,data_주일!AG$1:AG$303)>0,SUMIF(data_주일!$B:$B,$D17,data_주일!AG$1:AG$303),"") -> 25 | T17: =AVERAGE(M17:Q17) -> 25.8
D18: 21 | F18: 30 | G18: =IF(SUMIF(data_주일!$B$11:$B$303,$D18,data_주일!V$11:V$303)>0,SUMIF(data_주일!$B$11:$B$303,$D18,data_주일!V$11:V$303),"") -> 23 | H18: =IF(SUMIF(data_주일!$B$11:$B$303,$D18,data_주일!W$11:W$303)>0,SUMIF(data_주일!$B$11:$B$303,$D18,data_주일!W$11:W$303),"") -> 23 | I18: =IF(SUMIF(data_주일!$B$11:$B$303,$D18,data_주일!X$11:X$303)>0,SUMIF(data_주일!$B$11:$B$303,$D18,data_주일!X$11:X$303),"") -> 26 | J18: =IF(SUMIF(data_주일!$B$11:$B$303,$D18,data_주일!Y$11:Y$303)>0,SUMIF(data_주일!$B$11:$B$303,$D18,data_주일!Y$11:Y$303),"") -> 22 | K18: =IF(SUMIF(data_주일!$B$11:$B$303,$D18,data_주일!Z$11:Z$303)>0,SUMIF(data_주일!$B$11:$B$303,$D18,data_주일!Z$11:Z$303),"") -> 17 | L18: =IF(SUMIF(data_주일!$B$11:$B$303,$D18,data_주일!AA$11:AA$303)>0,SUMIF(data_주일!$B$11:$B$303,$D18,data_주일!AA$11:AA$303),"") -> 20 | M18: =IF(SUMIF(data_주일!$B$11:$B$303,$D18,data_주일!AB$11:AB$303)>0,SUMIF(data_주일!$B$11:$B$303,$D18,data_주일!AB$11:AB$303),"") -> 23 | N18: =IF(SUMIF(data_주일!$B$11:$B$303,$D18,data_주일!AC$11:AC$303)>0,SUMIF(data_주일!$B$11:$B$303,$D18,data_주일!AC$11:AC$303),"") -> 19 | O18: =IF(SUMIF(data_주일!$B$11:$B$303,$D18,data_주일!AD$11:AD$303)>0,SUMIF(data_주일!$B$11:$B$303,$D18,data_주일!AD$11:AD$303),"") -> 22 | P18: =IF(SUMIF(data_주일!$B:$B,$D18,data_주일!AE$1:AE$303)>0,SUMIF(data_주일!$B:$B,$D18,data_주일!AE$1:AE$303),"") -> 22 | Q18: =IF(SUMIF(data_주일!$B:$B,$D18,data_주일!AF$1:AF$303)>0,SUMIF(data_주일!$B:$B,$D18,data_주일!AF$1:AF$303),"") -> 18 | R18: =IF(SUMIF(data_주일!$B:$B,$D18,data_주일!AF$1:AF$303)>0,SUMIF(data_주일!$B:$B,$D18,data_주일!AF$1:AF$303),"") -> 18 | S18: =IF(SUMIF(data_주일!$B:$B,$D18,data_주일!AG$1:AG$303)>0,SUMIF(data_주일!$B:$B,$D18,data_주일!AG$1:AG$303),"") -> 20 | T18: =AVERAGE(M18:Q18) -> 20.8
D19: 22 | F19: 23 | G19: =IF(SUMIF(data_주일!$B$11:$B$303,$D19,data_주일!V$11:V$303)>0,SUMIF(data_주일!$B$11:$B$303,$D19,data_주일!V$11:V$303),"") -> 15 | H19: =IF(SUMIF(data_주일!$B$11:$B$303,$D19,data_주일!W$11:W$303)>0,SUMIF(data_주일!$B$11:$B$303,$D19,data_주일!W$11:W$303),"") -> 19 | I19: =IF(SUMIF(data_주일!$B$11:$B$303,$D19,data_주일!X$11:X$303)>0,SUMIF(data_주일!$B$11:$B$303,$D19,data_주일!X$11:X$303),"") -> 19 | J19: =IF(SUMIF(data_주일!$B$11:$B$303,$D19,data_주일!Y$11:Y$303)>0,SUMIF(data_주일!$B$11:$B$303,$D19,data_주일!Y$11:Y$303),"") -> 14 | K19: =IF(SUMIF(data_주일!$B$11:$B$303,$D19,data_주일!Z$11:Z$303)>0,SUMIF(data_주일!$B$11:$B$303,$D19,data_주일!Z$11:Z$303),"") -> 18 | L19: =IF(SUMIF(data_주일!$B$11:$B$303,$D19,data_주일!AA$11:AA$303)>0,SUMIF(data_주일!$B$11:$B$303,$D19,data_주일!AA$11:AA$303),"") -> 15 | M19: =IF(SUMIF(data_주일!$B$11:$B$303,$D19,data_주일!AB$11:AB$303)>0,SUMIF(data_주일!$B$11:$B$303,$D19,data_주일!AB$11:AB$303),"") -> 17 | N19: =IF(SUMIF(data_주일!$B$11:$B$303,$D19,data_주일!AC$11:AC$303)>0,SUMIF(data_주일!$B$11:$B$303,$D19,data_주일!AC$11:AC$303),"") -> 17 | O19: =IF(SUMIF(data_주일!$B$11:$B$303,$D19,data_주일!AD$11:AD$303)>0,SUMIF(data_주일!$B$11:$B$303,$D19,data_주일!AD$11:AD$303),"") -> 19 | P19: =IF(SUMIF(data_주일!$B:$B,$D19,data_주일!AE$1:AE$303)>0,SUMIF(data_주일!$B:$B,$D19,data_주일!AE$1:AE$303),"") -> 17 | Q19: =IF(SUMIF(data_주일!$B:$B,$D19,data_주일!AF$1:AF$303)>0,SUMIF(data_주일!$B:$B,$D19,data_주일!AF$1:AF$303),"") -> 16 | R19: =IF(SUMIF(data_주일!$B:$B,$D19,data_주일!AF$1:AF$303)>0,SUMIF(data_주일!$B:$B,$D19,data_주일!AF$1:AF$303),"") -> 16 | S19: =IF(SUMIF(data_주일!$B:$B,$D19,data_주일!AG$1:AG$303)>0,SUMIF(data_주일!$B:$B,$D19,data_주일!AG$1:AG$303),"") -> 16 | T19: =AVERAGE(M19:Q19) -> 17.2
D20: 31 | F20: 35 | G20: =IF(SUMIF(data_주일!$B$11:$B$303,$D20,data_주일!V$11:V$303)>0,SUMIF(data_주일!$B$11:$B$303,$D20,data_주일!V$11:V$303),"") -> 21 | H20: =IF(SUMIF(data_주일!$B$11:$B$303,$D20,data_주일!W$11:W$303)>0,SUMIF(data_주일!$B$11:$B$303,$D20,data_주일!W$11:W$303),"") -> 25 | I20: =IF(SUMIF(data_주일!$B$11:$B$303,$D20,data_주일!X$11:X$303)>0,SUMIF(data_주일!$B$11:$B$303,$D20,data_주일!X$11:X$303),"") -> 25 | J20: =IF(SUMIF(data_주일!$B$11:$B$303,$D20,data_주일!Y$11:Y$303)>0,SUMIF(data_주일!$B$11:$B$303,$D20,data_주일!Y$11:Y$303),"") -> 26 | K20: =IF(SUMIF(data_주일!$B$11:$B$303,$D20,data_주일!Z$11:Z$303)>0,SUMIF(data_주일!$B$11:$B$303,$D20,data_주일!Z$11:Z$303),"") -> 20 | L20: =IF(SUMIF(data_주일!$B$11:$B$303,$D20,data_주일!AA$11:AA$303)>0,SUMIF(data_주일!$B$11:$B$303,$D20,data_주일!AA$11:AA$303),"") -> 20 | M20: =IF(SUMIF(data_주일!$B$11:$B$303,$D20,data_주일!AB$11:AB$303)>0,SUMIF(data_주일!$B$11:$B$303,$D20,data_주일!AB$11:AB$303),"") -> 22 | N20: =IF(SUMIF(data_주일!$B$11:$B$303,$D20,data_주일!AC$11:AC$303)>0,SUMIF(data_주일!$B$11:$B$303,$D20,data_주일!AC$11:AC$303),"") -> 22 | O20: =IF(SUMIF(data_주일!$B$11:$B$303,$D20,data_주일!AD$11:AD$303)>0,SUMIF(data_주일!$B$11:$B$303,$D20,data_주일!AD$11:AD$303),"") -> 27 | P20: =IF(SUMIF(data_주일!$B:$B,$D20,data_주일!AE$1:AE$303)>0,SUMIF(data_주일!$B:$B,$D20,data_주일!AE$1:AE$303),"") -> 29 | Q20: =IF(SUMIF(data_주일!$B:$B,$D20,data_주일!AF$1:AF$303)>0,SUMIF(data_주일!$B:$B,$D20,data_주일!AF$1:AF$303),"") -> 25 | R20: =IF(SUMIF(data_주일!$B:$B,$D20,data_주일!AF$1:AF$303)>0,SUMIF(data_주일!$B:$B,$D20,data_주일!AF$1:AF$303),"") -> 25 | S20: =IF(SUMIF(data_주일!$B:$B,$D20,data_주일!AG$1:AG$303)>0,SUMIF(data_주일!$B:$B,$D20,data_주일!AG$1:AG$303),"") -> 26 | T20: =AVERAGE(M20:Q20) -> 25
D21: 32 | F21: 28 | G21: =IF(SUMIF(data_주일!$B$11:$B$303,$D21,data_주일!V$11:V$303)>0,SUMIF(data_주일!$B$11:$B$303,$D21,data_주일!V$11:V$303),"") -> 23 | H21: =IF(SUMIF(data_주일!$B$11:$B$303,$D21,data_주일!W$11:W$303)>0,SUMIF(data_주일!$B$11:$B$303,$D21,data_주일!W$11:W$303),"") -> 24 | I21: =IF(SUMIF(data_주일!$B$11:$B$303,$D21,data_주일!X$11:X$303)>0,SUMIF(data_주일!$B$11:$B$303,$D21,data_주일!X$11:X$303),"") -> 24 | J21: =IF(SUMIF(data_주일!$B$11:$B$303,$D21,data_주일!Y$11:Y$303)>0,SUMIF(data_주일!$B$11:$B$303,$D21,data_주일!Y$11:Y$303),"") -> 23 | K21: =IF(SUMIF(data_주일!$B$11:$B$303,$D21,data_주일!Z$11:Z$303)>0,SUMIF(data_주일!$B$11:$B$303,$D21,data_주일!Z$11:Z$303),"") -> 21 | L21: =IF(SUMIF(data_주일!$B$11:$B$303,$D21,data_주일!AA$11:AA$303)>0,SUMIF(data_주일!$B$11:$B$303,$D21,data_주일!AA$11:AA$303),"") -> 22 | M21: =IF(SUMIF(data_주일!$B$11:$B$303,$D21,data_주일!AB$11:AB$303)>0,SUMIF(data_주일!$B$11:$B$303,$D21,data_주일!AB$11:AB$303),"") -> 24 | N21: =IF(SUMIF(data_주일!$B$11:$B$303,$D21,data_주일!AC$11:AC$303)>0,SUMIF(data_주일!$B$11:$B$303,$D21,data_주일!AC$11:AC$303),"") -> 25 | O21: =IF(SUMIF(data_주일!$B$11:$B$303,$D21,data_주일!AD$11:AD$303)>0,SUMIF(data_주일!$B$11:$B$303,$D21,data_주일!AD$11:AD$303),"") -> 21 | P21: =IF(SUMIF(data_주일!$B:$B,$D21,data_주일!AE$1:AE$303)>0,SUMIF(data_주일!$B:$B,$D21,data_주일!AE$1:AE$303),"") -> 25 | Q21: =IF(SUMIF(data_주일!$B:$B,$D21,data_주일!AF$1:AF$303)>0,SUMIF(data_주일!$B:$B,$D21,data_주일!AF$1:AF$303),"") -> 24 | R21: =IF(SUMIF(data_주일!$B:$B,$D21,data_주일!AF$1:AF$303)>0,SUMIF(data_주일!$B:$B,$D21,data_주일!AF$1:AF$303),"") -> 24 | S21: =IF(SUMIF(data_주일!$B:$B,$D21,data_주일!AG$1:AG$303)>0,SUMIF(data_주일!$B:$B,$D21,data_주일!AG$1:AG$303),"") -> 24 | T21: =AVERAGE(M21:Q21) -> 23.8
D22: 33 | F22: 12 | G22: =IF(SUMIF(data_주일!$B$11:$B$303,$D22,data_주일!V$11:V$303)>0,SUMIF(data_주일!$B$11:$B$303,$D22,data_주일!V$11:V$303),"") -> 1 | H22: =IF(SUMIF(data_주일!$B$11:$B$303,$D22,data_주일!W$11:W$303)>0,SUMIF(data_주일!$B$11:$B$303,$D22,data_주일!W$11:W$303),"") -> 5 | I22: =IF(SUMIF(data_주일!$B$11:$B$303,$D22,data_주일!X$11:X$303)>0,SUMIF(data_주일!$B$11:$B$303,$D22,data_주일!X$11:X$303),"") -> 6 | J22: =IF(SUMIF(data_주일!$B$11:$B$303,$D22,data_주일!Y$11:Y$303)>0,SUMIF(data_주일!$B$11:$B$303,$D22,data_주일!Y$11:Y$303),"") -> 6 | K22: =IF(SUMIF(data_주일!$B$11:$B$303,$D22,data_주일!Z$11:Z$303)>0,SUMIF(data_주일!$B$11:$B$303,$D22,data_주일!Z$11:Z$303),"") -> 2 | L22: =IF(SUMIF(data_주일!$B$11:$B$303,$D22,data_주일!AA$11:AA$303)>0,SUMIF(data_주일!$B$11:$B$303,$D22,data_주일!AA$11:AA$303),"") | M22: =IF(SUMIF(data_주일!$B$11:$B$303,$D22,data_주일!AB$11:AB$303)>0,SUMIF(data_주일!$B$11:$B$303,$D22,data_주일!AB$11:AB$303),"") -> 5 | N22: =IF(SUMIF(data_주일!$B$11:$B$303,$D22,data_주일!AC$11:AC$303)>0,SUMIF(data_주일!$B$11:$B$303,$D22,data_주일!AC$11:AC$303),"") -> 4 | O22: =IF(SUMIF(data_주일!$B$11:$B$303,$D22,data_주일!AD$11:AD$303)>0,SUMIF(data_주일!$B$11:$B$303,$D22,data_주일!AD$11:AD$303),"") -> 6 | P22: =IF(SUMIF(data_주일!$B:$B,$D22,data_주일!AE$1:AE$303)>0,SUMIF(data_주일!$B:$B,$D22,data_주일!AE$1:AE$303),"") -> 5 | Q22: =IF(SUMIF(data_주일!$B:$B,$D22,data_주일!AF$1:AF$303)>0,SUMIF(data_주일!$B:$B,$D22,data_주일!AF$1:AF$303),"") -> 5 | R22: =IF(SUMIF(data_주일!$B:$B,$D22,data_주일!AF$1:AF$303)>0,SUMIF(data_주일!$B:$B,$D22,data_주일!AF$1:AF$303),"") -> 5 | S22: =IF(SUMIF(data_주일!$B:$B,$D22,data_주일!AG$1:AG$303)>0,SUMIF(data_주일!$B:$B,$D22,data_주일!AG$1:AG$303),"") -> 4 | T22: =AVERAGE(M22:Q22) -> 5
D23: 41 | F23: 30 | G23: =IF(SUMIF(data_주일!$B$11:$B$303,$D23,data_주일!V$11:V$303)>0,SUMIF(data_주일!$B$11:$B$303,$D23,data_주일!V$11:V$303),"") -> 23 | H23: =IF(SUMIF(data_주일!$B$11:$B$303,$D23,data_주일!W$11:W$303)>0,SUMIF(data_주일!$B$11:$B$303,$D23,data_주일!W$11:W$303),"") -> 21 | I23: =IF(SUMIF(data_주일!$B$11:$B$303,$D23,data_주일!X$11:X$303)>0,SUMIF(data_주일!$B$11:$B$303,$D23,data_주일!X$11:X$303),"") -> 20 | J23: =IF(SUMIF(data_주일!$B$11:$B$303,$D23,data_주일!Y$11:Y$303)>0,SUMIF(data_주일!$B$11:$B$303,$D23,data_주일!Y$11:Y$303),"") -> 24 | K23: =IF(SUMIF(data_주일!$B$11:$B$303,$D23,data_주일!Z$11:Z$303)>0,SUMIF(data_주일!$B$11:$B$303,$D23,data_주일!Z$11:Z$303),"") -> 24 | L23: =IF(SUMIF(data_주일!$B$11:$B$303,$D23,data_주일!AA$11:AA$303)>0,SUMIF(data_주일!$B$11:$B$303,$D23,data_주일!AA$11:AA$303),"") -> 23 | M23: =IF(SUMIF(data_주일!$B$11:$B$303,$D23,data_주일!AB$11:AB$303)>0,SUMIF(data_주일!$B$11:$B$303,$D23,data_주일!AB$11:AB$303),"") -> 22 | N23: =IF(SUMIF(data_주일!$B$11:$B$303,$D23,data_주일!AC$11:AC$303)>0,SUMIF(data_주일!$B$11:$B$303,$D23,data_주일!AC$11:AC$303),"") -> 22 | O23: =IF(SUMIF(data_주일!$B$11:$B$303,$D23,data_주일!AD$11:AD$303)>0,SUMIF(data_주일!$B$11:$B$303,$D23,data_주일!AD$11:AD$303),"") -> 15 | P23: =IF(SUMIF(data_주일!$B:$B,$D23,data_주일!AE$1:AE$303)>0,SUMIF(data_주일!$B:$B,$D23,data_주일!AE$1:AE$303),"") -> 19 | Q23: =IF(SUMIF(data_주일!$B:$B,$D23,data_주일!AF$1:AF$303)>0,SUMIF(data_주일!$B:$B,$D23,data_주일!AF$1:AF$303),"") -> 24 | R23: =IF(SUMIF(data_주일!$B:$B,$D23,data_주일!AF$1:AF$303)>0,SUMIF(data_주일!$B:$B,$D23,data_주일!AF$1:AF$303),"") -> 24 | S23: =IF(SUMIF(data_주일!$B:$B,$D23,data_주일!AG$1:AG$303)>0,SUMIF(data_주일!$B:$B,$D23,data_주일!AG$1:AG$303),"") -> 24 | T23: =AVERAGE(M23:Q23) -> 20.4
D24: 42 | F24: 29 | G24: =IF(SUMIF(data_주일!$B$11:$B$303,$D24,data_주일!V$11:V$303)>0,SUMIF(data_주일!$B$11:$B$303,$D24,data_주일!V$11:V$303),"") -> 18 | H24: =IF(SUMIF(data_주일!$B$11:$B$303,$D24,data_주일!W$11:W$303)>0,SUMIF(data_주일!$B$11:$B$303,$D24,data_주일!W$11:W$303),"") -> 13 | I24: =IF(SUMIF(data_주일!$B$11:$B$303,$D24,data_주일!X$11:X$303)>0,SUMIF(data_주일!$B$11:$B$303,$D24,data_주일!X$11:X$303),"") -> 22 | J24: =IF(SUMIF(data_주일!$B$11:$B$303,$D24,data_주일!Y$11:Y$303)>0,SUMIF(data_주일!$B$11:$B$303,$D24,data_주일!Y$11:Y$303),"") -> 19 | K24: =IF(SUMIF(data_주일!$B$11:$B$303,$D24,data_주일!Z$11:Z$303)>0,SUMIF(data_주일!$B$11:$B$303,$D24,data_주일!Z$11:Z$303),"") -> 22 | L24: =IF(SUMIF(data_주일!$B$11:$B$303,$D24,data_주일!AA$11:AA$303)>0,SUMIF(data_주일!$B$11:$B$303,$D24,data_주일!AA$11:AA$303),"") -> 24 | M24: =IF(SUMIF(data_주일!$B$11:$B$303,$D24,data_주일!AB$11:AB$303)>0,SUMIF(data_주일!$B$11:$B$303,$D24,data_주일!AB$11:AB$303),"") -> 23 | N24: =IF(SUMIF(data_주일!$B$11:$B$303,$D24,data_주일!AC$11:AC$303)>0,SUMIF(data_주일!$B$11:$B$303,$D24,data_주일!AC$11:AC$303),"") -> 23 | O24: =IF(SUMIF(data_주일!$B$11:$B$303,$D24,data_주일!AD$11:AD$303)>0,SUMIF(data_주일!$B$11:$B$303,$D24,data_주일!AD$11:AD$303),"") -> 23 | P24: =IF(SUMIF(data_주일!$B:$B,$D24,data_주일!AE$1:AE$303)>0,SUMIF(data_주일!$B:$B,$D24,data_주일!AE$1:AE$303),"") -> 24 | Q24: =IF(SUMIF(data_주일!$B:$B,$D24,data_주일!AF$1:AF$303)>0,SUMIF(data_주일!$B:$B,$D24,data_주일!AF$1:AF$303),"") -> 22 | R24: =IF(SUMIF(data_주일!$B:$B,$D24,data_주일!AF$1:AF$303)>0,SUMIF(data_주일!$B:$B,$D24,data_주일!AF$1:AF$303),"") -> 22 | S24: =IF(SUMIF(data_주일!$B:$B,$D24,data_주일!AG$1:AG$303)>0,SUMIF(data_주일!$B:$B,$D24,data_주일!AG$1:AG$303),"") -> 20 | T24: =AVERAGE(M24:Q24) -> 23
D25: 43 | F25: 34 | G25: =IF(SUMIF(data_주일!$B$11:$B$303,$D25,data_주일!V$11:V$303)>0,SUMIF(data_주일!$B$11:$B$303,$D25,data_주일!V$11:V$303),"") -> 23 | H25: =IF(SUMIF(data_주일!$B$11:$B$303,$D25,data_주일!W$11:W$303)>0,SUMIF(data_주일!$B$11:$B$303,$D25,data_주일!W$11:W$303),"") -> 23 | I25: =IF(SUMIF(data_주일!$B$11:$B$303,$D25,data_주일!X$11:X$303)>0,SUMIF(data_주일!$B$11:$B$303,$D25,data_주일!X$11:X$303),"") -> 22 | J25: =IF(SUMIF(data_주일!$B$11:$B$303,$D25,data_주일!Y$11:Y$303)>0,SUMIF(data_주일!$B$11:$B$303,$D25,data_주일!Y$11:Y$303),"") -> 26 | K25: =IF(SUMIF(data_주일!$B$11:$B$303,$D25,data_주일!Z$11:Z$303)>0,SUMIF(data_주일!$B$11:$B$303,$D25,data_주일!Z$11:Z$303),"") -> 26 | L25: =IF(SUMIF(data_주일!$B$11:$B$303,$D25,data_주일!AA$11:AA$303)>0,SUMIF(data_주일!$B$11:$B$303,$D25,data_주일!AA$11:AA$303),"") -> 22 | M25: =IF(SUMIF(data_주일!$B$11:$B$303,$D25,data_주일!AB$11:AB$303)>0,SUMIF(data_주일!$B$11:$B$303,$D25,data_주일!AB$11:AB$303),"") -> 28 | N25: =IF(SUMIF(data_주일!$B$11:$B$303,$D25,data_주일!AC$11:AC$303)>0,SUMIF(data_주일!$B$11:$B$303,$D25,data_주일!AC$11:AC$303),"") -> 25 | O25: =IF(SUMIF(data_주일!$B$11:$B$303,$D25,data_주일!AD$11:AD$303)>0,SUMIF(data_주일!$B$11:$B$303,$D25,data_주일!AD$11:AD$303),"") -> 25 | P25: =IF(SUMIF(data_주일!$B:$B,$D25,data_주일!AE$1:AE$303)>0,SUMIF(data_주일!$B:$B,$D25,data_주일!AE$1:AE$303),"") -> 25 | Q25: =IF(SUMIF(data_주일!$B:$B,$D25,data_주일!AF$1:AF$303)>0,SUMIF(data_주일!$B:$B,$D25,data_주일!AF$1:AF$303),"") -> 25 | R25: =IF(SUMIF(data_주일!$B:$B,$D25,data_주일!AF$1:AF$303)>0,SUMIF(data_주일!$B:$B,$D25,data_주일!AF$1:AF$303),"") -> 25 | S25: =IF(SUMIF(data_주일!$B:$B,$D25,data_주일!AG$1:AG$303)>0,SUMIF(data_주일!$B:$B,$D25,data_주일!AG$1:AG$303),"") -> 23 | T25: =AVERAGE(M25:Q25) -> 25.6
C26: 교회학교 | F26: 유초 | G26: 10 | H26: 12 | I26: 11 | J26: 8 | K26: 8 | L26: 10 | M26: 11 | N26: 8 | O26: 12 | P26: 14 | Q26: 10 | T26: =AVERAGE(M26:Q26) -> 11
F27: 중고 | G27: 19 | H27: 21 | I27: 16 | J27: 16 | K27: 17 | L27: 20 | M27: 18 | N27: 17 | O27: 17 | P27: 19 | Q27: 17 | T27: =AVERAGE(M27:Q27) -> 17.6
C28: 합계 | G28: =IF(SUM(G14,G26,G27)>0,SUM(G14,G26,G27),"") -> 226 | H28: =IF(SUM(H14,H26,H27)>0,SUM(H14,H26,H27),"") -> 226 | I28: =IF(SUM(I14,I26,I27)>0,SUM(I14,I26,I27),"") -> 243 | J28: =IF(SUM(J14,J26,J27)>0,SUM(J14,J26,J27),"") -> 236 | K28: =IF(SUM(K14,K26,K27)>0,SUM(K14,K26,K27),"") -> 226 | L28: =IF(SUM(L14,L26,L27)>0,SUM(L14,L26,L27),"") -> 228 | M28: =IF(SUM(M14,M26,M27)>0,SUM(M14,M26,M27),"") -> 241 | N28: =IF(SUM(N14,N26,N27)>0,SUM(N14,N26,N27),"") -> 235 | ... S28: =IF(SUM(S14,S26,S27)>0,SUM(S14,S26,S27),"") -> 202 | T28: =AVERAGE(M28:Q28) -> 238.4
C29: ※ 유초등부, 중고등부는 별도 파악하여 입력
C42: 명단 | D42: 인도자 | F42: 구역 | G42: 45752 | H42: 45759 | I42: 45766 | J42: 45773 | K42: =K13 -> 45780 | L42: =L13 -> 45787 | M42: =M13 -> 45794 | N42: =N13 -> 45801 | O42: =O13 -> 45808 | P42: =P13 -> 45815 | Q42: =Q13 -> 45822 | R42: =R13 -> 45829 | S42: =S13 -> 45835
C43: =IF(data_주일!C309="","",data_주일!C309) -> 윤나영 | D43: =IF(data_주일!D309="","",data_주일!D309) -> 최경숙 | F43: =IF(data_주일!B309="","",data_주일!B309) -> 11 | G43: =IF(data_주일!V309=1,$C43,"") | H43: =IF(data_주일!W309=1,$C43,"") | I43: =IF(data_주일!X309=1,$C43,"") | J43: =IF(data_주일!Y309=1,$C43,"") | K43: =IF(data_주일!Z309=1,$C43,"") | L43: =IF(data_주일!AA309=1,$C43,"") | M43: =IF(data_주일!AB309=1,$C43,"") | N43: =IF(data_주일!AC309=1,$C43,"") | ... Q43: =IF(data_주일!AF309=1,$C43,"") | R43: =IF(data_주일!AF309=1,$C43,"") | S43: =IF(data_주일!AG309=1,$C43,"")
